Workbook

Sheet EVENT-to-A_Weekday
A1: Last Updated: | B1: 45345 | C1: Z1 | D1: =SORT(A2:A14, ROW(A2:A14), 0)
A2: STATION | B2: COORDINATES | C2: 4400 | D2: 4402 | E2: 4420
A3: DE WILDT | B3: -25.624641315648187, 27.944111334913465 | C3: 0.19444444 | D3: 0.3125 | E3: 0.68402778
A4: TAILLARDSHOOP | B4: -25.617806769500547, 27.972401220150644 | C4: 0.19791667 | D4: 0.31597222 | E4: 0.6875
A5: GA-RANKUWA | B5: -25.619463521827942, 27.991787773598496 | C5: 0.2 | D5: 0.31805556 | E5: 0.68958333
A6: ROSSLYN | B6: -25.637700722357806, 28.094920182723996 | C6: 0.20833333 | D6: 0.32638889 | E6: 0.69791667
A7: WINTERSNEST | B7: -25.646665143468105, 28.128664081235527 | C7: 0.21180556 | D7: 0.32986111 | E7: 0.70138889
A8: WOLMERTON | B8: -25.656754583256834, 28.166308537943245 | C8: 0.21597222 | D8: 0.33402778 | E8: 0.70555556
A9: PRETORIA-N | B9: -25.672156912459837, 28.181972182122085 | C9: 0.21875 | D9: 0.33680556 | E9: 0.70833333
A10: MOUNTAIN VIEW | B10: -25.701154966265122, 28.1710407244521 | C10: 0.22361111 | D10: 0.34166667 | E10: 0.71319444
A11: HERCULES | B11: -25.724426332570793, 28.16740145328856 | C11: 0.22708333 | D11: 0.34513889 | E11: 0.71666667
A12: PRETORIA WES | B12: -25.75612607001734, 28.167454033423436 | C12: 0.23194444 | D12: 0.35 | E12: 0.72152778
A13: PRETORIA | B13: -25.75864361043285, 28.189866445989118 | C13: 0.23611111 | D13: 0.35416667 | E13: 0.72569444

Sheet EVENT-to-B_Weekday
A1: Last Updated: | B1: 45345 | C1: Z1 | D1: =SORT(A2:A14, ROW(A2:A14), 0)
A2: STATION | B2: COORDINATES | C2: 4400 | D2: 4402 | E2: 4420
A3: DE WILDT | B3: -25.624641315648187, 27.944111334913465 | C3: 0.19444444 | D3: 0.3125 | E3: 0.68402778
A4: TAILLARDSHOOP | B4: -25.617806769500547, 27.972401220150644 | C4: 0.19791667 | D4: 0.31597222 | E4: 0.6875
A5: GA-RANKUWA | B5: -25.619463521827942, 27.991787773598496 | C5: 0.2 | D5: 0.31805556 | E5: 0.68958333
A6: ROSSLYN | B6: -25.637700722357806, 28.094920182723996 | C6: 0.20833333 | D6: 0.32638889 | E6: 0.69791667
A7: WINTERSNEST | B7: -25.646665143468105, 28.128664081235527 | C7: 0.21180556 | D7: 0.32986111 | E7: 0.70138889
A8: WOLMERTON | B8: -25.656754583256834, 28.166308537943245 | C8: 0.21597222 | D8: 0.33402778 | E8: 0.70555556
A9: PRETORIA-N | B9: -25.672156912459837, 28.181972182122085 | C9: 0.21875 | D9: 0.33680556 | E9: 0.70833333
A10: MOUNTAIN VIEW | B10: -25.701154966265122, 28.1710407244521 | C10: 0.22361111 | D10: 0.34166667 | E10: 0.71319444
A11: HERCULES | B11: -25.724426332570793, 28.16740145328856 | C11: 0.22708333 | D11: 0.34513889 | E11: 0.71666667
A12: PRETORIA WES | B12: -25.75612607001734, 28.167454033423436 | C12: 0.23194444 | D12: 0.35 | E12: 0.72152778
A13: PRETORIA | B13: -25.75864361043285, 28.189866445989118 | C13: 0.23611111 | D13: 0.35416667 | E13: 0.72569444

Sheet EVENT-to-A_Sat
A1: Last Updated: | B1: 45345 | C1: Z1 | D1: =SORT(A2:A14, ROW(A2:A14), 0)
A2: STATION | B2: COORDINATES | C2: 4400 | D2: 4402 | E2: 4420
A3: DE WILDT | B3: -25.624641315648187, 27.944111334913465 | C3: 0.19444444 | D3: 0.3125 | E3: 0.68402778
A4: TAILLARDSHOOP | B4: -25.617806769500547, 27.972401220150644 | C4: 0.19791667 | D4: 0.31597222 | E4: 0.6875
A5: GA-RANKUWA | B5: -25.619463521827942, 27.991787773598496 | C5: 0.2 | D5: 0.31805556 | E5: 0.68958333
A6: ROSSLYN | B6: -25.637700722357806, 28.094920182723996 | C6: 0.20833333 | D6: 0.32638889 | E6: 0.69791667
A7: WINTERSNEST | B7: -25.646665143468105, 28.128664081235527 | C7: 0.21180556 | D7: 0.32986111 | E7: 0.70138889
A8: WOLMERTON | B8: -25.656754583256834, 28.166308537943245 | C8: 0.21597222 | D8: 0.33402778 | E8: 0.70555556
A9: PRETORIA-N | B9: -25.672156912459837, 28.181972182122085 | C9: 0.21875 | D9: 0.33680556 | E9: 0.70833333
A10: MOUNTAIN VIEW | B10: -25.701154966265122, 28.1710407244521 | C10: 0.22361111 | D10: 0.34166667 | E10: 0.71319444
A11: HERCULES | B11: -25.724426332570793, 28.16740145328856 | C11: 0.22708333 | D11: 0.34513889 | E11: 0.71666667
A12: PRETORIA WES | B12: -25.75612607001734, 28.167454033423436 | C12: 0.23194444 | D12: 0.35 | E12: 0.72152778
A13: PRETORIA | B13: -25.75864361043285, 28.189866445989118 | C13: 0.23611111 | D13: 0.35416667 | E13: 0.72569444

Sheet EVENT-to-B_Sat
A1: Last Updated: | B1: 45345 | C1: Z1 | D1: =SORT(A2:A14, ROW(A2:A14), 0)
A2: STATION | B2: COORDINATES | C2: 4400 | D2: 4402 | E2: 4420
A3: DE WILDT | B3: -25.624641315648187, 27.944111334913465 | C3: 0.19444444 | D3: 0.3125 | E3: 0.68402778
A4: TAILLARDSHOOP | B4: -25.617806769500547, 27.972401220150644 | C4: 0.19791667 | D4: 0.31597222 | E4: 0.6875
A5: GA-RANKUWA | B5: -25.619463521827942, 27.991787773598496 | C5: 0.2 | D5: 0.31805556 | E5: 0.68958333
A6: ROSSLYN | B6: -25.637700722357806, 28.094920182723996 | C6: 0.20833333 | D6: 0.32638889 | E6: 0.69791667
A7: WINTERSNEST | B7: -25.646665143468105, 28.128664081235527 | C7: 0.21180556 | D7: 0.32986111 | E7: 0.70138889
A8: WOLMERTON | B8: -25.656754583256834, 28.166308537943245 | C8: 0.21597222 | D8: 0.33402778 | E8: 0.70555556
A9: PRETORIA-N | B9: -25.672156912459837, 28.181972182122085 | C9: 0.21875 | D9: 0.33680556 | E9: 0.70833333
A10: MOUNTAIN VIEW | B10: -25.701154966265122, 28.1710407244521 | C10: 0.22361111 | D10: 0.34166667 | E10: 0.71319444
A11: HERCULES | B11: -25.724426332570793, 28.16740145328856 | C11: 0.22708333 | D11: 0.34513889 | E11: 0.71666667
A12: PRETORIA WES | B12: -25.75612607001734, 28.167454033423436 | C12: 0.23194444 | D12: 0.35 | E12: 0.72152778
A13: PRETORIA | B13: -25.75864361043285, 28.189866445989118 | C13: 0.23611111 | D13: 0.35416667 | E13: 0.72569444

Sheet ABC-to-ABC_Weekday
A1: Last Updated: | B1: 45345 | C1: Z1 | D1: =SORT(A2:A14, ROW(A2:A14), 0)
A2: STATION | B2: COORDINATES | C2: 4400 | D2: 4402 | E2: 4420
A3: DE WILDT | B3: -25.624641315648187, 27.944111334913465 | C3: 0.19444444 | D3: 0.3125 | E3: 0.68402778
A4: TAILLARDSHOOP | B4: -25.617806769500547, 27.972401220150644 | C4: 0.19791667 | D4: 0.31597222 | E4: 0.6875
A5: GA-RANKUWA | B5: -25.619463521827942, 27.991787773598496 | C5: 0.2 | D5: 0.31805556 | E5: 0.68958333
A6: ROSSLYN | B6: -25.637700722357806, 28.094920182723996 | C6: 0.20833333 | D6: 0.32638889 | E6: 0.69791667
A7: WINTERSNEST | B7: -25.646665143468105, 28.128664081235527 | C7: 0.21180556 | D7: 0.32986111 | E7: 0.70138889
A8: WOLMERTON | B8: -25.656754583256834, 28.166308537943245 | C8: 0.21597222 | D8: 0.33402778 | E8: 0.70555556
A9: PRETORIA-N | B9: -25.672156912459837, 28.181972182122085 | C9: 0.21875 | D9: 0.33680556 | E9: 0.70833333
A10: MOUNTAIN VIEW | B10: -25.701154966265122, 28.1710407244521 | C10: 0.22361111 | D10: 0.34166667 | E10: 0.71319444
A11: HERCULES | B11: -25.724426332570793, 28.16740145328856 | C11: 0.22708333 | D11: 0.34513889 | E11: 0.71666667
A12: PRETORIA WES | B12: -25.75612607001734, 28.167454033423436 | C12: 0.23194444 | D12: 0.35 | E12: 0.72152778
A13: PRETORIA | B13: -25.75864361043285, 28.189866445989118 | C13: 0.23611111 | D13: 0.35416667 | E13: 0.72569444

Sheet Archive_2025

Sheet Config_GridOrder
A1: Key,SheetName,RowNumber,StartCol
A2: durbn-to-umlaz_weekday,DURBN-to-UMLAZ_Weekday,2,C
A3: umlaz-to-durbn_weekday,UMLAZ-to-DURBN_Weekday,2,C
A4: durbn-to-umlaz_sat,DURBN-to-UMLAZ_Sat,2,C
A5: umlaz-to-durbn_sat,UMLAZ-to-DURBN_Sat,2,C
A6: durbn-to-bridg_weekday,DURBN-to-BRIDG_Weekday,2,C
A7: bridg-to-durbn_weekday,BRIDG-to-DURBN_Weekday,2,C
A8: durbn-to-bridg_sat,DURBN-to-BRIDG_Sat,2,C
A9: bridg-to-durbn_sat,BRIDG-to-DURBN_Sat,2,C
A10: durbn-to-winkl_weekday,DURBN-to-WINKL_Weekday,2,C
A11: winkl-to-durbn_weekday,WINKL-to-DURBN_Weekday,2,C
A12: durbn-to-winkl_sat,DURBN-to-WINKL_Sat,2,C
... A29: event_to_b_sat,EVENT-to-B_Sat,2,C

Sheet DURBN-to-UMLAZ_Weekday
A1: Last Updated: | B1: 46230 | C1: Z2
A2: STATION | B2: COORDINATES | C2: 9110 | D2: 9130 | E2: 9140 | F2: 9150 | G2: 9160 | H2: 9170 | I2: 9180 | J2: 9190 | K2: 9210 | L2: 9220 | M2: 9230 | N2: 9240 | O2: 9244 | P2: 9250 | Q2: 9254 | R2: 9264 | S2: 9274
A3: DURBAN YARD | B3: -29.834333, 31.026139 | I3: 0.47361111 | L3: 0.59861111 | M3: 0.64027778 | P3: 0.72361111
A4: DURBAN | B4: -29.84489056762199, 31.022357088460843 | C4: 0.20625 | D4: 0.27013889 | E4: 0.31180556 | F4: 0.35347222 | G4: 0.39513889 | H4: 0.43680556 | I4: 0.47847222 | J4: 0.52013889 | K4: 0.56180556 | L4: 0.60347222 | M4: 0.64513889 | N4: 0.68680556 | O4: 0.70763889 | P4: 0.72847222 | Q4: 0.74930556 | R4: 0.79097222 | S4: 0.83263889
A5: BEREA ROAD | B5: -29.85714656237288, 31.012251554171158 | C5: 0.20833333 | D5: 0.27222222 | E5: 0.31388889 | F5: 0.35555556 | G5: 0.39722222 | H5: 0.43888889 | I5: 0.48055556 | J5: 0.52222222 | K5: 0.56388889 | L5: 0.60555556 | M5: 0.64722222 | N5: 0.68888889 | O5: 0.70972222 | P5: 0.73055556 | Q5: =Q4+P5-P4 -> 0.75138889 | R5: =R4+Q5-Q4 -> 0.79305556 | S5: =S4+R5-R4 -> 0.83472222
A6: DALBRIDGE | B6: -29.86800762596781, 31.00631745346827 | C6: 0.2125 | D6: 0.27638889 | E6: 0.31805556 | F6: 0.35972222 | G6: 0.40138889 | H6: 0.44305556 | I6: 0.48472222 | J6: 0.52638889 | K6: 0.56805556 | L6: 0.60972222 | M6: 0.65138889 | N6: 0.69305556 | O6: 0.71388889 | P6: 0.73472222 | Q6: =Q5+P6-P5 -> 0.75555556 | R6: =R5+Q6-Q5 -> 0.79722222 | S6: =S5+R6-R5 -> 0.83888889
A7: CONGELLA | B7: -29.877804214443714, 30.996696619770805 | C7: 0.21597222 | D7: 0.27986111 | E7: 0.32152778 | F7: 0.36319444 | G7: 0.40486111 | H7: 0.44652778 | I7: 0.48819444 | J7: 0.52986111 | K7: 0.57152778 | L7: 0.61319444 | M7: 0.65486111 | N7: 0.69652778 | O7: 0.71736111 | P7: 0.73819444 | Q7: =Q6+P7-P6 -> 0.75902778 | R7: =R6+Q7-Q6 -> 0.80069444 | S7: =S6+R7-R6 -> 0.84236111
A8: UMBILO | B8: -29.890408568248482, 30.984596995797897 | C8: 0.21875 | D8: 0.28263889 | E8: 0.32430556 | F8: 0.36597222 | G8: 0.40763889 | H8: 0.44930556 | I8: 0.49097222 | J8: 0.53263889 | K8: 0.57430556 | L8: 0.61597222 | M8: 0.65763889 | N8: 0.69930556 | O8: 0.72013889 | P8: 0.74097222 | Q8: =Q7+P8-P7 -> 0.76180556 | R8: =R7+Q8-Q7 -> 0.80347222 | S8: =S7+R8-R7 -> 0.84513889
A9: ROSSBURGH | B9: -29.89943479406536, 30.98049926990544 | C9: 0.22430556 | D9: 0.28819444 | E9: 0.32986111 | F9: 0.37152778 | G9: 0.41319444 | H9: 0.45486111 | I9: 0.49652778 | J9: 0.53819444 | K9: 0.57986111 | L9: 0.62152778 | M9: 0.66319444 | N9: 0.70486111 | O9: 0.72569444 | P9: 0.74652778 | Q9: =Q8+P9-P8 -> 0.76736111 | R9: =R8+Q9-Q8 -> 0.80902778 | S9: =S8+R9-R8 -> 0.85069444
A10: CLAIRWOOD | B10: -29.91586685921378, 30.976185952436662 | C10: 0.22916667 | D10: 0.29305556 | E10: 0.33472222 | F10: 0.37638889 | G10: 0.41805556 | H10: 0.45972222 | I10: 0.50138889 | J10: 0.54305556 | K10: 0.58472222 | L10: 0.62638889 | M10: 0.66805556 | N10: 0.70972222 | O10: 0.73055556 | P10: 0.75138889 | Q10: =Q9+P10-P9 -> 0.77222222 | R10: =R9+Q10-Q9 -> 0.81388889 | S10: =S9+R10-R9 -> 0.85555556
A11: MONTCLAIR | B11: -29.911973683567116, 30.97489973301122 | C11: 0.23333333 | D11: 0.29722222 | E11: 0.33888889 | F11: 0.38055556 | G11: 0.42222222 | H11: 0.46388889 | I11: 0.50555556 | J11: 0.54722222 | K11: 0.58888889 | L11: 0.63055556 | M11: 0.67222222 | N11: 0.71388889 | O11: 0.73472222 | P11: 0.75555556 | Q11: =Q10+P11-P10 -> 0.77638889 | R11: =R10+Q11-Q10 -> 0.81805556 | S11: =S10+R11-R10 -> 0.85972222
A12: MEREBANK | B12: -29.943867324872905, 30.958701026485713 | C12: 0.23888889 | D12: 0.30277778 | E12: 0.34444444 | F12: 0.38611111 | G12: 0.42777778 | H12: 0.46944444 | I12: 0.51111111 | J12: 0.55277778 | K12: 0.59444444 | L12: 0.63611111 | M12: 0.67777778 | N12: 0.71944444 | O12: 0.74027778 | P12: 0.76111111 | Q12: =Q11+P12-P11 -> 0.78194444 | R12: =R11+Q12-Q11 -> 0.82361111 | S12: =S11+R12-R11 -> 0.86527778
A13: REUNION | B13: -29.963225890304287, 30.941094166965776 | C13: 0.24513889 | D13: 0.30902778 | E13: 0.35069444 | F13: 0.39236111 | G13: 0.43402778 | H13: 0.47569444 | I13: 0.51736111 | J13: 0.55902778 | K13: 0.60069444 | L13: 0.64236111 | M13: 0.68402778 | N13: 0.72569444 | O13: 0.74652778 | P13: 0.76736111 | Q13: =Q12+P13-P12 -> 0.78819444 | R13: =R12+Q13-Q12 -> 0.82986111 | S13: =S12+R13-R12 -> 0.87152778
A14: ZWELETHU | B14: -29.963504795525992, 30.91693283813006 | C14: 0.25 | D14: 0.31388889 | E14: 0.35555556 | F14: 0.39722222 | G14: 0.43888889 | H14: 0.48055556 | I14: 0.52222222 | J14: 0.56388889 | K14: 0.60555556 | L14: 0.64722222 | M14: 0.68888889 | N14: 0.73055556 | O14: 0.75138889 | P14: 0.77222222 | Q14: =Q13+P14-P13 -> 0.79305556 | R14: =R13+Q14-Q13 -> 0.83472222 | S14: =S13+R14-R13 -> 0.87638889
A15: kwaMNYANDU | B15: -29.972439080929043, 30.90418256696626 | C15: 0.25347222 | D15: 0.31736111 | E15: 0.35902778 | F15: 0.40069444 | G15: 0.44236111 | H15: 0.48402778 | I15: 0.52569444 | J15: 0.56736111 | K15: 0.60902778 | L15: 0.65069444 | M15: 0.69236111 | N15: 0.73402778 | O15: 0.75486111 | P15: 0.77569444 | Q15: =Q14+P15-P14 -> 0.79652778 | R15: =R14+Q15-Q14 -> 0.83819444 | S15: =S14+R15-R14 -> 0.87986111
A16: LINDOKUHLE | B16: -29.95934086046813, 30.88875892463683 | C16: 0.25694444 | D16: 0.32083333 | E16: 0.3625 | F16: 0.40416667 | G16: 0.44583333 | H16: 0.4875 | I16: 0.52916667 | J16: 0.57083333 | K16: 0.6125 | L16: 0.65416667 | M16: 0.69583333 | N16: 0.7375 | O16: 0.75833333 | P16: 0.77916667 | Q16: =Q15+P16-P15 -> 0.8 | R16: =R15+Q16-Q15 -> 0.84166667 | S16: =S15+R16-R15 -> 0.88333333
A17: UMLAZI | B17: -29.953969074951846, 30.866029768629286 | C17: 0.26041667 | D17: 0.32430556 | E17: 0.36597222 | F17: 0.40763889 | G17: 0.44930556 | H17: 0.49097222 | I17: 0.53263889 | J17: 0.57430556 | K17: 0.61597222 | L17: 0.65763889 | M17: 0.69930556 | N17: 0.74097222 | O17: 0.76180556 | P17: 0.78263889 | Q17: =Q16+P17-P16 -> 0.80347222 | R17: =R16+Q17-Q16 -> 0.84513889 | S17: =S16+R17-R16 -> 0.88680556

Sheet UMLAZ-to-DURBN_Weekday
A1: Last Updated: | B1: ='DURBN-to-UMLAZ_Weekday'!B1 -> 46230 | C1: ='DURBN-to-UMLAZ_Weekday'!C1 -> Z2
A2: STATION | B2: COORDINATES | C2: 9113 | D2: 9119 | E2: 9123 | F2: 9133 | G2: 9139 | H2: 9143 | I2: 9153 | J2: 9163 | K2: 9173 | L2: 9183 | M2: 9203 | N2: 9213 | O2: 9223 | P2: 9233 | Q2: 9243 | R2: 9253 | S2: 9277 | T2: 9287
A3: UMLAZI | B3: -29.953969074951846, 30.866029768629286 | C3: 0.16458333 | D3: 0.18541667 | E3: 0.20625 | F3: 0.22708333 | H3: 0.26875 | I3: 0.33125 | J3: 0.37291667 | K3: 0.41458333 | L3: 0.45625 | M3: 0.49791667 | N3: 0.53958333 | O3: 0.58125 | P3: 0.62291667 | Q3: 0.66458333 | R3: 0.70625 | S3: 0.81041667 | T3: 0.85208333
A4: LINDOKUHLE | B4: -29.95934086046813, 30.88875892463683 | C4: 0.16805556 | D4: 0.18888889 | E4: 0.20972222 | F4: 0.23055556 | H4: 0.27222222 | I4: 0.33472222 | J4: 0.37638889 | K4: 0.41805556 | L4: 0.45972222 | M4: 0.50138889 | N4: 0.54305556 | O4: 0.58472222 | P4: 0.62638889 | Q4: 0.66805556 | R4: 0.70972222 | S4: 0.81388889 | T4: 0.85555556
A5: kwaMNYANDU | B5: -29.972439080929043, 30.90418256696626 | C5: 0.17222222 | D5: 0.19305556 | E5: 0.21388889 | F5: 0.23472222 | G5: 0.25833333 | H5: 0.27638889 | I5: 0.33888889 | J5: 0.38055556 | K5: 0.42222222 | L5: 0.46388889 | M5: 0.50555556 | N5: 0.54722222 | O5: 0.58888889 | P5: 0.63055556 | Q5: 0.67222222 | R5: 0.71388889 | S5: 0.81805556 | T5: 0.85972222
A6: ZWELETHU | B6: -29.963504795525992, 30.91693283813006 | C6: 0.17638889 | D6: 0.19722222 | E6: 0.21805556 | F6: 0.23888889 | G6: 0.2625 | H6: 0.28055556 | I6: 0.34305556 | J6: 0.38472222 | K6: 0.42638889 | L6: 0.46805556 | M6: 0.50972222 | N6: 0.55138889 | O6: 0.59305556 | P6: 0.63472222 | Q6: 0.67638889 | R6: 0.71805556 | S6: 0.82222222 | T6: 0.86388889
A7: REUNION | B7: -29.963225890304287, 30.941094166965776 | C7: 0.18263889 | D7: 0.20347222 | E7: 0.22430556 | F7: 0.24513889 | G7: 0.26875 | H7: 0.28680556 | I7: 0.34930556 | J7: 0.39097222 | K7: 0.43263889 | L7: 0.47430556 | M7: 0.51597222 | N7: 0.55763889 | O7: 0.59930556 | P7: 0.64097222 | Q7: 0.68263889 | R7: 0.72430556 | S7: 0.82847222 | T7: 0.87013889
A8: MEREBANK | B8: -29.943867324872905, 30.958701026485713 | C8: 0.18819444 | D8: 0.20902778 | E8: 0.22986111 | F8: 0.25069444 | G8: 0.27430556 | H8: 0.29236111 | I8: 0.35486111 | J8: 0.39652778 | K8: 0.43819444 | L8: 0.47986111 | M8: 0.52152778 | N8: 0.56319444 | O8: 0.60486111 | P8: 0.64652778 | Q8: 0.68819444 | R8: 0.72986111 | S8: 0.83402778 | T8: 0.87569444
A9: MONTCLAIR | B9: -29.911973683567116, 30.97489973301122 | C9: 0.19166667 | D9: 0.2125 | E9: 0.23333333 | F9: 0.25416667 | G9: 0.27777778 | H9: 0.29583333 | I9: 0.35833333 | J9: 0.4 | K9: 0.44166667 | L9: 0.48333333 | M9: 0.525 | N9: 0.56666667 | O9: 0.60833333 | P9: 0.65 | Q9: 0.69166667 | R9: 0.73333333 | S9: 0.8375 | T9: 0.87916667
A10: CLAIRWOOD | B10: -29.91586685921378, 30.976185952436662 | C10: 0.19652778 | D10: 0.21736111 | E10: 0.23819444 | F10: 0.25902778 | G10: 0.28263889 | H10: 0.30069444 | I10: 0.36319444 | J10: 0.40486111 | K10: 0.44652778 | L10: 0.48819444 | M10: 0.52986111 | N10: 0.57152778 | O10: 0.61319444 | P10: 0.65486111 | Q10: 0.69652778 | R10: 0.73819444 | S10: 0.84236111 | T10: 0.88402778
A11: ROSSBURGH | B11: -29.89943479406536, 30.98049926990544 | C11: 0.20069444 | D11: 0.22152778 | E11: 0.24236111 | F11: 0.26319444 | G11: 0.28680556 | H11: 0.30486111 | I11: 0.36736111 | J11: 0.40902778 | K11: 0.45069444 | L11: 0.49236111 | M11: 0.53402778 | N11: 0.57569444 | O11: 0.61736111 | P11: 0.65902778 | Q11: 0.70069444 | R11: 0.74236111 | S11: 0.84652778 | T11: 0.88819444
A12: UMBILO | B12: -29.890408568248482, 30.984596995797897 | C12: 0.20555556 | D12: 0.22638889 | E12: 0.24722222 | F12: 0.26805556 | G12: 0.29166667 | H12: 0.30972222 | I12: 0.37222222 | J12: 0.41388889 | K12: 0.45555556 | L12: 0.49722222 | M12: 0.53888889 | N12: 0.58055556 | O12: 0.62222222 | P12: 0.66388889 | Q12: 0.70555556 | R12: 0.74722222 | S12: 0.85138889 | T12: 0.89305556
A13: CONGELLA | B13: -29.877804214443714, 30.996696619770805 | C13: 0.20902778 | D13: 0.22986111 | E13: 0.25069444 | F13: 0.27152778 | G13: 0.29513889 | H13: 0.31319444 | I13: 0.37569444 | J13: 0.41736111 | K13: 0.45902778 | L13: 0.50069444 | M13: 0.54236111 | N13: 0.58402778 | O13: 0.62569444 | P13: 0.66736111 | Q13: 0.70902778 | R13: 0.75069444 | S13: 0.85486111 | T13: 0.89652778
A14: DALBRIDGE | B14: -29.86800762596781, 31.00631745346827 | C14: 0.21319444 | D14: 0.23402778 | E14: 0.25486111 | F14: 0.27569444 | G14: 0.29930556 | H14: 0.31736111 | I14: 0.37986111 | J14: 0.42152778 | K14: 0.46319444 | L14: 0.50486111 | M14: 0.54652778 | N14: 0.58819444 | O14: 0.62986111 | P14: 0.67152778 | Q14: 0.71319444 | R14: 0.75486111 | S14: 0.85902778 | T14: 0.90069444
A15: BEREA ROAD | B15: -29.85714656237288, 31.012251554171158 | C15: 0.21527778 | D15: 0.23611111 | E15: 0.25694444 | F15: 0.27777778 | G15: 0.30138889 | H15: 0.31944444 | I15: 0.38194444 | J15: 0.42361111 | K15: 0.46527778 | L15: 0.50694444 | M15: 0.54861111 | N15: 0.59027778 | O15: 0.63194444 | P15: 0.67361111 | Q15: 0.71527778 | R15: 0.75694444 | S15: 0.86111111 | T15: 0.90277778
A16: DURBAN | B16: -29.84489056762199, 31.022357088460843 | C16: 0.21875 | D16: 0.23958333 | E16: 0.26041667 | F16: 0.28125 | G16: 0.30486111 | H16: 0.32291667 | I16: 0.38541667 | J16: 0.42708333 | K16: 0.46875 | L16: 0.51041667 | M16: 0.55208333 | N16: 0.59375 | O16: 0.63541667 | P16: 0.67708333 | Q16: 0.71875 | R16: 0.76041667 | S16: 0.86458333 | T16: 0.90625
A17: DURBAN YARD | B17: -29.834333, 31.026139 | D17: 0.24444444 | F17: 0.28611111 | H17: 0.32777778 | L17: 0.51527778 | N17: 0.59861111 | O17: 0.64027778 | R17: 0.76527778 | S17: 0.86944444 | T17: 0.91111111

Sheet DURBN-to-UMLAZ_Sat
A1: Last Updated: | B1: 46230 | C1: ='DURBN-to-UMLAZ_Weekday'!C1 -> Z2
A2: STATION | B2: COORDINATES | C2: 9130 | D2: 9140 | E2: 9150 | F2: 9170 | G2: 9204 | H2: 9230 | I2: 9260 | J2: 9270 | K2: 9280
A3: DURBAN YARD | B3: -29.834333, 31.026139 | C3: 0.16111111 | F3: 0.32777778 | G3: 0.45277778 | H3: 0.61944444
A4: DURBAN | B4: -29.84489056762199, 31.022357088460843 | C4: 0.16597222 | D4: 0.20763889 | E4: 0.24930556 | F4: 0.37430556 | G4: 0.49930556 | H4: 0.62430556 | I4: 0.70763889 | J4: 0.74930556 | K4: 0.79097222
A5: BEREA ROAD | B5: -29.85714656237288, 31.012251554171158 | C5: 0.16805556 | D5: =D4+C5-C4 -> 0.20972222 | E5: 0.25138889 | F5: 0.37638889 | G5: 0.50138889 | H5: 0.62638889 | I5: 0.70972222 | J5: 0.75138889 | K5: 0.79305556
A6: DALBRIDGE | B6: -29.86800762596781, 31.00631745346827 | C6: 0.17222222 | D6: =D5+C6-C5 -> 0.21388889 | E6: 0.25555556 | F6: 0.38055556 | G6: 0.50555556 | H6: 0.63055556 | I6: 0.71388889 | J6: 0.75555556 | K6: 0.79722222
A7: CONGELLA | B7: -29.877804214443714, 30.996696619770805 | C7: 0.17569444 | D7: =D6+C7-C6 -> 0.21736111 | E7: 0.25902778 | F7: 0.38402778 | G7: 0.50902778 | H7: 0.63402778 | I7: 0.71736111 | J7: 0.75902778 | K7: 0.80069444
A8: UMBILO | B8: -29.890408568248482, 30.984596995797897 | C8: 0.17847222 | D8: =D7+C8-C7 -> 0.22013889 | E8: 0.26180556 | F8: 0.38680556 | G8: 0.51180556 | H8: 0.63680556 | I8: 0.72013889 | J8: 0.76180556 | K8: 0.80347222
A9: ROSSBURGH | B9: -29.89943479406536, 30.98049926990544 | C9: 0.18402778 | D9: =D8+C9-C8 -> 0.22569444 | E9: 0.26736111 | F9: 0.39236111 | G9: 0.51736111 | H9: 0.64236111 | I9: 0.72569444 | J9: 0.76736111 | K9: 0.80902778
A10: CLAIRWOOD | B10: -29.91586685921378, 30.976185952436662 | C10: 0.18888889 | D10: =D9+C10-C9 -> 0.23055556 | E10: 0.27222222 | F10: 0.39722222 | G10: 0.52222222 | H10: 0.64722222 | I10: 0.73055556 | J10: 0.77222222 | K10: 0.81388889
A11: MONTCLAIR | B11: -29.911973683567116, 30.97489973301122 | C11: 0.19305556 | D11: =D10+C11-C10 -> 0.23472222 | E11: 0.27638889 | F11: 0.40138889 | G11: 0.52638889 | H11: 0.65138889 | I11: 0.73472222 | J11: 0.77638889 | K11: 0.81805556
A12: MEREBANK | B12: -29.943867324872905, 30.958701026485713 | C12: 0.19861111 | D12: =D11+C12-C11 -> 0.24027778 | E12: 0.28194444 | F12: 0.40694444 | G12: 0.53194444 | H12: 0.65694444 | I12: 0.74027778 | J12: 0.78194444 | K12: 0.82361111
A13: REUNION | B13: -29.963225890304287, 30.941094166965776 | C13: 0.20486111 | D13: =D12+C13-C12 -> 0.24652778 | E13: 0.28819444 | F13: 0.41319444 | G13: 0.53819444 | H13: 0.66319444 | I13: 0.74652778 | J13: 0.78819444 | K13: 0.82986111
A14: ZWELETHU | B14: -29.963504795525992, 30.91693283813006 | C14: 0.20972222 | D14: =D13+C14-C13 -> 0.25138889 | E14: 0.29305556 | F14: 0.41805556 | G14: 0.54305556 | H14: 0.66805556 | I14: 0.75138889 | J14: 0.79305556 | K14: 0.83472222
A15: kwaMNYANDU | B15: -29.972439080929043, 30.90418256696626 | C15: 0.21319444 | D15: =D14+C15-C14 -> 0.25486111 | E15: 0.29652778 | F15: 0.42152778 | G15: 0.54652778 | H15: 0.67152778 | I15: 0.75486111 | J15: 0.79652778 | K15: 0.83819444
A16: LINDOKUHLE | B16: -29.95934086046813, 30.88875892463683 | C16: 0.21666667 | D16: =D15+C16-C15 -> 0.25833333 | E16: 0.3 | F16: 0.425 | G16: 0.55 | H16: 0.675 | I16: 0.75833333 | J16: 0.8 | K16: 0.84166667
A17: UMLAZI | B17: -29.953969074951846, 30.866029768629286 | C17: 0.22013889 | D17: =D16+C17-C16 -> 0.26180556 | E17: 0.30347222 | F17: 0.42847222 | G17: 0.55347222 | H17: 0.67847222 | I17: 0.76180556 | J17: 0.80347222 | K17: 0.84513889

Sheet UMLAZ-to-DURBN_Sat
A1: Last Updated: | B1: ='DURBN-to-UMLAZ_Sat'!B1 -> 46230 | C1: ='DURBN-to-UMLAZ_Weekday'!C1 -> Z2
A2: STATION | B2: COORDINATES | C2: 9129 | D2: 9139 | E2: 9149 | F2: 9159 | G2: 9179 | H2: 9209 | I2: 9239 | J2: 9259 | K2: 9279
A3: UMLAZI | B3: -29.953969074951846, 30.866029768629286 | C3: 0.18541667 | D3: 0.22708333 | E3: 0.26875 | F3: 0.31041667 | G3: 0.35208333 | H3: 0.43541667 | I3: 0.64375 | J3: 0.68541667 | K3: 0.76875
A4: LINDOKUHLE | B4: -29.95934086046813, 30.88875892463683 | C4: 0.18888889 | D4: 0.23055556 | E4: 0.27222222 | F4: =F3+E4-E3 -> 0.31388889 | G4: 0.35555556 | H4: 0.43888889 | I4: 0.64722222 | J4: 0.68888889 | K4: 0.77222222
A5: kwaMNYANDU | B5: -29.972439080929043, 30.90418256696626 | C5: 0.19305556 | D5: 0.23472222 | E5: 0.27638889 | F5: =F4+E5-E4 -> 0.31805556 | G5: 0.35972222 | H5: 0.44305556 | I5: 0.65138889 | J5: 0.69305556 | K5: 0.77638889
A6: ZWELETHU | B6: -29.963504795525992, 30.91693283813006 | C6: 0.19722222 | D6: 0.23888889 | E6: 0.28055556 | F6: =F5+E6-E5 -> 0.32222222 | G6: 0.36388889 | H6: 0.44722222 | I6: 0.65555556 | J6: 0.69722222 | K6: 0.78055556
A7: REUNION | B7: -29.963225890304287, 30.941094166965776 | C7: 0.20347222 | D7: 0.24513889 | E7: 0.28680556 | F7: =F6+E7-E6 -> 0.32847222 | G7: 0.37013889 | H7: 0.45347222 | I7: 0.66180556 | J7: 0.70347222 | K7: 0.78680556
A8: MEREBANK | B8: -29.943867324872905, 30.958701026485713 | C8: 0.20902778 | D8: 0.25069444 | E8: 0.29236111 | F8: =F7+E8-E7 -> 0.33402778 | G8: 0.37569444 | H8: 0.45902778 | I8: 0.66736111 | J8: 0.70902778 | K8: 0.79236111
A9: MONTCLAIR | B9: -29.911973683567116, 30.97489973301122 | C9: 0.2125 | D9: 0.25416667 | E9: 0.29583333 | F9: =F8+E9-E8 -> 0.3375 | G9: 0.37916667 | H9: 0.4625 | I9: 0.67083333 | J9: 0.7125 | K9: 0.79583333
A10: CLAIRWOOD | B10: -29.91586685921378, 30.976185952436662 | C10: 0.21736111 | D10: 0.25902778 | E10: 0.30069444 | F10: =F9+E10-E9 -> 0.34236111 | G10: 0.38402778 | H10: 0.46736111 | I10: 0.67569444 | J10: 0.71736111 | K10: 0.80069444
A11: ROSSBURGH | B11: -29.89943479406536, 30.98049926990544 | C11: 0.22152778 | D11: 0.26319444 | E11: 0.30486111 | F11: =F10+E11-E10 -> 0.34652778 | G11: 0.38819444 | H11: 0.47152778 | I11: 0.67986111 | J11: 0.72152778 | K11: 0.80486111
A12: UMBILO | B12: -29.890408568248482, 30.984596995797897 | C12: 0.22638889 | D12: 0.26805556 | E12: 0.30972222 | F12: =F11+E12-E11 -> 0.35138889 | G12: 0.39305556 | H12: 0.47638889 | I12: 0.68472222 | J12: 0.72638889 | K12: 0.80972222
A13: CONGELLA | B13: -29.877804214443714, 30.996696619770805 | C13: 0.22986111 | D13: 0.27152778 | E13: 0.31319444 | F13: =F12+E13-E12 -> 0.35486111 | G13: 0.39652778 | H13: 0.47986111 | I13: 0.68819444 | J13: 0.72986111 | K13: 0.81319444
A14: DALBRIDGE | B14: -29.86800762596781, 31.00631745346827 | C14: 0.23402778 | D14: 0.27569444 | E14: 0.31736111 | F14: =F13+E14-E13 -> 0.35902778 | G14: 0.40069444 | H14: 0.48402778 | I14: 0.69236111 | J14: 0.73402778 | K14: 0.81736111
A15: BEREA ROAD | B15: -29.85714656237288, 31.012251554171158 | C15: 0.23611111 | D15: 0.27777778 | E15: 0.31944444 | F15: =F14+E15-E14 -> 0.36111111 | G15: 0.40277778 | H15: 0.48611111 | I15: 0.69444444 | J15: 0.73611111 | K15: 0.81944444
A16: DURBAN | B16: -29.84489056762199, 31.022357088460843 | C16: 0.23958333 | D16: 0.28125 | E16: 0.32291667 | F16: =F15+E16-E15 -> 0.36458333 | G16: 0.40625 | H16: 0.48958333 | I16: 0.69791667 | J16: 0.73958333 | K16: 0.82291667
A17: DURBAN YARD | B17: -29.834333, 31.026139 | E17: 0.32777778 | H17: 0.49444444 | I17: 0.41111111 | J17: 0.74444444 | K17: 0.82777778

Sheet DURBN-to-BRIDG_Weekday
A1: Last Updated: | B1: 46230 | C1: Z2
A2: STATION | B2: COORDINATES | C2: 9313 | D2: 9715 | E2: 9323 | F2: 9723 | G2: 9333 | H2: 9729 | I2: 9353 | J2: 9739 | K2: 9373 | L2: 9749 | M2: 9383 | N2: 9755 | O2: 9393 | P2: 9759 | Q2: 9403 | R2: 9763 | S2: 9413 | T2: 9767 | U2: 9423 | V2: 9771 | W2: 9433 | X2: 9775 | Y2: 9443 | Z2: 9779 | AA2: 9453 | AB2: 9783 | AC2: 9463 | AD2: 9787 | AE2: 9473 | AF2: 9791
A3: BEREA ROAD | B3: -29.85714656237288, 31.012251554171158 | C3: 0.17569444 | E3: 0.20347222 | G3: 0.27291667 | I3: 0.35625 | K3: 0.43958333 | M3: 0.52291667 | O3: 0.56458333 | Q3: 0.60625 | S3: 0.64791667 | U3: 0.66180556 | W3: 0.67569444 | Y3: 0.68958333 | AA3: 0.71736111 | AC3: 0.74513889 | AE3: 0.81458333
A4: DURBAN | B4: -29.84489056762199, 31.022357088460843 | C4: 0.17986111 | E4: 0.20763889 | G4: 0.27708333 | I4: 0.36041667 | K4: 0.44375 | M4: 0.52708333 | O4: 0.56875 | Q4: 0.61041667 | S4: 0.65208333 | U4: 0.66597222 | W4: 0.67986111 | Y4: 0.69375 | AA4: 0.72152778 | AC4: 0.74930556 | AE4: 0.81875
A5: MOSES MABHIDA | B5: -29.828174437586064, 31.03164291113771 | C5: 0.18263889 | E5: 0.21041667 | G5: 0.27986111 | I5: 0.36319444 | K5: 0.44652778 | M5: 0.52986111 | O5: 0.57152778 | Q5: 0.61319444 | S5: 0.65486111 | U5: 0.66875 | W5: 0.68263889 | Y5: 0.69652778 | AA5: 0.72430556 | AC5: 0.75208333 | AE5: 0.82152778
A6: UMGENI | B6: -29.81680605847883, 31.02742038505348 | C6: 0.18541667 | E6: 0.21319444 | G6: 0.28263889 | I6: 0.36597222 | K6: 0.44930556 | M6: 0.53263889 | O6: 0.57430556 | Q6: 0.61597222 | S6: 0.65763889 | U6: 0.67152778 | W6: 0.68541667 | Y6: 0.69930556 | AA6: 0.72708333 | AC6: 0.75486111 | AE6: 0.82430556
A7: BRIARDENE | B7: -29.796700991231464, 31.01418868183359 | C7: 0.19027778 | E7: 0.21805556 | G7: 0.2875 | I7: 0.37083333 | K7: 0.45416667 | M7: 0.5375 | O7: 0.57916667 | Q7: 0.62083333 | S7: 0.6625 | U7: 0.67638889 | W7: 0.69027778 | Y7: 0.70416667 | AA7: 0.73194444 | AC7: 0.75972222 | AE7: 0.82916667
A8: GREENWOOD PARK | B8: -29.78886303102557, 31.019987033178655 | C8: 0.19305556 | E8: 0.22083333 | G8: 0.29027778 | I8: 0.37361111 | K8: 0.45694444 | M8: 0.54027778 | O8: 0.58194444 | Q8: 0.62361111 | S8: 0.66527778 | U8: 0.67916667 | W8: 0.69305556 | Y8: 0.70694444 | AA8: 0.73472222 | AC8: 0.7625 | AE8: 0.83194444
A9: RED HILL | B9: -29.77881199269451, 31.02278786426192 | C9: 0.19513889 | E9: 0.22291667 | G9: 0.29236111 | I9: 0.37569444 | K9: 0.45902778 | M9: 0.54236111 | O9: 0.58402778 | Q9: 0.62569444 | S9: 0.66736111 | U9: 0.68125 | W9: 0.69513889 | Y9: 0.70902778 | AA9: 0.73680556 | AC9: 0.76458333 | AE9: 0.83402778
A10: AVOCA | B10: -29.760772221994845, 31.021557341565032 | C10: 0.19930556 | E10: 0.22708333 | G10: 0.29652778 | I10: 0.37986111 | K10: 0.46319444 | M10: 0.54652778 | O10: 0.58819444 | Q10: 0.62986111 | S10: 0.67152778 | U10: 0.68541667 | W10: 0.69930556 | Y10: 0.71319444 | AA10: 0.74097222 | AC10: 0.76875 | AE10: 0.83819444
A11: TEMPLE | B11: -29.803794322749017, 31.00594296514886
A12: KENVILLE | B12: -29.79223460755487, 31.00131508045099
A13: EFFINGHAM | B13: -29.771484689837905, 31.002467628997902
A14: DUFF'S ROAD | B14: -29.743381167737063, 31.00438746386499 | C14: 0.20486111 | D14: 0.20902778 | E14: 0.23263889 | F14: 0.23472222 | G14: 0.30208333 | H14: 0.31388889 | I14: 0.38541667 | J14: 0.39722222 | K14: 0.46875 | L14: 0.48055556 | M14: 0.55208333 | N14: 0.56388889 | O14: 0.59375 | P14: 0.60555556 | Q14: 0.63541667 | R14: 0.64722222 | S14: 0.67708333 | T14: 0.68125 | U14: 0.69097222 | V14: 0.69930556 | W14: 0.70486111 | X14: 0.70625 | Y14: 0.71875 | Z14: 0.72013889 | AA14: 0.74652778 | AB14: 0.75069444 | AC14: 0.77430556 | AD14: 0.77638889 | AE14: 0.84375 | AF14: 0.84583333
A15: TEMBALIHLE | B15: -29.74232619650293, 30.99327039689171 | C15: 0.20763889 | E15: 0.23541667 | G15: 0.30486111 | I15: 0.38819444 | K15: 0.47152778 | M15: 0.55486111 | O15: 0.59652778 | Q15: 0.63819444 | S15: 0.67986111 | U15: 0.69375 | W15: 0.70763889 | Y15: 0.72152778 | AA15: 0.74930556 | AC15: 0.77708333 | AE15: 0.84652778
A16: kwaMASHU | B16: -29.750076129548816, 30.9736385977492 | C16: 0.21041667 | E16: 0.23819444 | G16: 0.30763889 | I16: 0.39097222 | K16: 0.47430556 | M16: 0.55763889 | O16: 0.59930556 | Q16: 0.64097222 | S16: 0.68263889 | U16: 0.69652778 | W16: 0.71041667 | Y16: 0.72430556 | AA16: 0.75208333 | AC16: 0.77986111 | AE16: 0.84930556
A17: BRIDGE CITY | B17: -29.726914572007956, 30.986441559931276 | D17: 0.21319444 | F17: 0.23888889 | H17: 0.31805556 | J17: 0.40138889 | L17: 0.48472222 | N17: 0.56805556 | P17: 0.60972222 | R17: 0.65138889 | T17: 0.68541667 | V17: 0.70347222 | X17: 0.71041667 | Z17: 0.72430556 | AB17: 0.75486111 | AD17: 0.78055556 | AF17: 0.85

Sheet BRIDG-to-DURBN_Weekday
A1: Last Updated: | B1: ='DURBN-to-BRIDG_Weekday'!B1 -> 46230 | C1: ='DURBN-to-BRIDG_Weekday'!C1 -> Z2
A2: STATION | B2: COORDINATES | C2: 9712 | D2: 9314 | E2: 9716 | F2: 9324 | G2: 9720 | H2: 9334 | I2: 9724 | J2: 9344 | K2: 9728 | L2: 9354 | M2: 9732 | N2: 9364 | O2: 9736 | P2: 9374 | Q2: 9742 | R2: 9384 | S2: 9748 | T2: 9404 | U2: 9754 | V2: 9414 | W2: 9758 | X2: 9424 | Y2: 9762 | Z2: 9434 | AA2: 9772 | AB2: 9444 | AC2: 9776 | AD2: 9454 | AE2: 9782 | AF2: 9464
A3: BRIDGE CITY | B3: -29.726914572007956, 30.986441559931276 | C3: 0.17222222 | E3: 0.2 | G3: 0.22777778 | I3: 0.24166667 | K3: 0.25555556 | M3: 0.26944444 | O3: 0.30416667 | Q3: 0.3875 | S3: 0.47083333 | U3: 0.55416667 | W3: 0.59583333 | Y3: 0.6375 | AA3: 0.71111111 | AC3: 0.74166667 | AE3: 0.78055556
A4: kwaMASHU | B4: -29.750076129548816, 30.9736385977492 | D4: 0.175 | F4: 0.20277778 | H4: 0.23055556 | J4: 0.24444444 | L4: 0.25833333 | N4: 0.27222222 | P4: 0.31388889 | R4: 0.39722222 | T4: 0.48055556 | V4: 0.56388889 | X4: 0.60555556 | Z4: 0.64722222 | AB4: 0.71666667 | AD4: 0.74444444 | AF4: 0.78611111
A5: TEMBALIHLE | B5: -29.74232619650293, 30.99327039689171 | D5: 0.17708333 | F5: 0.20486111 | H5: 0.23263889 | J5: 0.24652778 | L5: 0.26041667 | N5: 0.27430556 | P5: 0.31597222 | R5: 0.39930556 | T5: 0.48263889 | V5: 0.56597222 | X5: 0.60763889 | Z5: 0.64930556 | AB5: 0.71875 | AD5: 0.74652778 | AF5: 0.78819444
A6: DUFF'S ROAD | B6: -29.743381167737063, 31.00438746386499 | C6: 0.17638889 | D6: 0.18055556 | E6: 0.20416667 | F6: 0.20833333 | G6: 0.23194444 | H6: 0.23611111 | I6: 0.24583333 | J6: 0.25 | K6: 0.25972222 | L6: 0.26388889 | M6: 0.27361111 | N6: 0.27777778 | O6: 0.30833333 | P6: 0.31944444 | Q6: 0.39166667 | R6: 0.40277778 | S6: 0.475 | T6: 0.48611111 | U6: 0.55833333 | V6: 0.56944444 | W6: 0.6 | X6: 0.61111111 | Y6: 0.64166667 | Z6: 0.65277778 | AA6: 0.71527778 | AB6: 0.72222222 | AC6: 0.74583333 | AD6: 0.75 | AE6: 0.78472222 | AF6: 0.79166667
A7: EFFINGHAM | B7: -29.771484689837905, 31.002467628997902
A8: KENVILLE | B8: -29.79223460755487, 31.00131508045099
A9: TEMPLE | B9: -29.803794322749017, 31.00594296514886
A10: AVOCA | B10: -29.760772221994845, 31.021557341565032 | D10: 0.18680556 | F10: 0.21458333 | H10: 0.24236111 | J10: 0.25625 | L10: 0.27013889 | N10: 0.28402778 | P10: 0.32569444 | R10: 0.40902778 | T10: 0.49236111 | V10: 0.57569444 | X10: 0.61736111 | Z10: 0.65902778 | AB10: 0.72847222 | AD10: 0.75625 | AF10: 0.79791667
A11: RED HILL | B11: -29.77881199269451, 31.02278786426192 | D11: 0.19027778 | F11: 0.21805556 | H11: 0.24583333 | J11: 0.25972222 | L11: 0.27361111 | N11: 0.2875 | P11: 0.32916667 | R11: 0.4125 | T11: 0.49583333 | V11: 0.57916667 | X11: 0.62083333 | Z11: 0.6625 | AB11: 0.73194444 | AD11: 0.75972222 | AF11: 0.80138889
A12: GREENWOOD PARK | B12: -29.78886303102557, 31.019987033178655 | D12: 0.19305556 | F12: 0.22083333 | H12: 0.24861111 | J12: 0.2625 | L12: 0.27638889 | N12: 0.29027778 | P12: 0.33194444 | R12: 0.41527778 | T12: 0.49861111 | V12: 0.58194444 | X12: 0.62361111 | Z12: 0.66527778 | AB12: 0.73472222 | AD12: 0.7625 | AF12: 0.80416667
A13: BRIARDENE | B13: -29.796700991231464, 31.01418868183359 | D13: 0.19513889 | F13: 0.22291667 | H13: 0.25069444 | J13: 0.26458333 | L13: 0.27847222 | N13: 0.29236111 | P13: 0.33402778 | R13: 0.41736111 | T13: 0.50069444 | V13: 0.58402778 | X13: 0.62569444 | Z13: 0.66736111 | AB13: 0.73680556 | AD13: 0.76458333 | AF13: 0.80625
A14: UMGENI | B14: -29.81680605847883, 31.02742038505348 | D14: 0.2 | F14: 0.22777778 | H14: 0.25555556 | J14: 0.26944444 | L14: 0.28333333 | N14: 0.29722222 | P14: 0.33888889 | R14: 0.42222222 | T14: 0.50555556 | V14: 0.58888889 | X14: 0.63055556 | Z14: 0.67222222 | AB14: 0.74166667 | AD14: 0.76944444 | AF14: 0.81111111
A15: MOSES MABHIDA | B15: -29.828174437586064, 31.03164291113771 | D15: 0.20138889 | F15: 0.22916667 | H15: 0.25694444 | J15: 0.27083333 | L15: 0.28472222 | N15: 0.29861111 | P15: 0.34027778 | R15: 0.42361111 | T15: 0.50694444 | V15: 0.59027778 | X15: 0.63194444 | Z15: 0.67361111 | AB15: 0.74305556 | AD15: 0.77083333 | AF15: 0.8125
A16: DURBAN | B16: -29.84489056762199, 31.022357088460843 | D16: 0.20555556 | F16: 0.23333333 | H16: 0.26111111 | J16: 0.275 | L16: 0.28888889 | N16: 0.30277778 | P16: 0.34444444 | R16: 0.42777778 | T16: 0.51111111 | V16: 0.59444444 | X16: 0.63611111 | Z16: 0.67777778 | AB16: 0.74722222 | AD16: 0.775 | AF16: 0.81666667
A17: BEREA ROAD | B17: -29.85714656237288, 31.012251554171158 | D17: 0.20902778 | F17: 0.23680556 | H17: 0.26458333 | J17: 0.27847222 | L17: 0.29236111 | N17: 0.30625 | P17: 0.34791667 | R17: 0.43125 | T17: 0.51458333 | V17: 0.59791667 | X17: 0.63958333 | Z17: 0.68125 | AB17: 0.75069444 | AD17: 0.77847222 | AF17: 0.82013889

Sheet DURBN-to-BRIDG_Sat
A1: Last Updated: | B1: 46076 | C1: ='DURBN-to-BRIDG_Weekday'!C1 -> Z2
A2: STATION | B2: COORDINATES | C2: 9323 | D2: 9333 | E2: 9729 | F2: 9373 | G2: 9749 | H2: 9393 | I2: 9759 | J2: 9413 | K2: 9767 | L2: 9443 | M2: 9779 | N2: 9463 | O2: 9787 | P2: 9473 | Q2: 9791
A3: BEREA ROAD | B3: -29.85714656237288, 31.012251554171158 | C3: 0.20347222 | D3: 0.27291667 | F3: 0.43958333 | H3: 0.56458333 | J3: 0.64791667 | L3: 0.68958333 | N3: 0.74513889 | P3: 0.81458333
A4: DURBAN | B4: -29.84489056762199, 31.022357088460843 | C4: 0.20763889 | D4: 0.27708333 | F4: 0.44375 | H4: 0.56875 | J4: 0.65208333 | L4: 0.69375 | N4: 0.74930556 | P4: 0.81875
A5: MOSES MABHIDA | B5: -29.828174437586064, 31.03164291113771 | C5: 0.21041667 | D5: 0.27986111 | F5: 0.44652778 | H5: 0.57152778 | J5: 0.65486111 | L5: 0.69652778 | N5: 0.75208333 | P5: 0.82152778
A6: UMGENI | B6: -29.81680605847883, 31.02742038505348 | C6: 0.21319444 | D6: 0.28263889 | F6: 0.44930556 | H6: 0.57430556 | J6: 0.65763889 | L6: 0.69930556 | N6: 0.75486111 | P6: 0.82430556
A7: BRIARDENE | B7: -29.796700991231464, 31.01418868183359 | C7: 0.21805556 | D7: 0.2875 | F7: 0.45416667 | H7: 0.57916667 | J7: 0.6625 | L7: 0.70416667 | N7: 0.75972222 | P7: 0.82916667
A8: GREENWOOD PARK | B8: -29.78886303102557, 31.019987033178655 | C8: 0.22083333 | D8: 0.29027778 | F8: 0.45694444 | H8: 0.58194444 | J8: 0.66527778 | L8: 0.70694444 | N8: 0.7625 | P8: 0.83194444
A9: RED HILL | B9: -29.77881199269451, 31.02278786426192 | C9: 0.22291667 | D9: 0.29236111 | F9: 0.45902778 | H9: 0.58402778 | J9: 0.66736111 | L9: 0.70902778 | N9: 0.76458333 | P9: 0.83402778
A10: AVOCA | B10: -29.760772221994845, 31.021557341565032 | C10: 0.22708333 | D10: 0.29652778 | F10: 0.46319444 | H10: 0.58819444 | J10: 0.67152778 | L10: 0.71319444 | N10: 0.76875 | P10: 0.83819444
A11: TEMPLE | B11: -29.803794322749017, 31.00594296514886
A12: KENVILLE | B12: -29.79223460755487, 31.00131508045099
A13: EFFINGHAM | B13: -29.771484689837905, 31.002467628997902
A14: DUFF'S ROAD | B14: -29.743381167737063, 31.00438746386499 | C14: 0.23263889 | D14: 0.30208333 | E14: 0.31388889 | F14: 0.46875 | G14: 0.48055556 | H14: 0.59375 | I14: 0.60555556 | J14: 0.67708333 | K14: 0.68125 | L14: 0.71875 | M14: 0.72013889 | N14: 0.77430556 | O14: 0.77638889 | P14: 0.84375 | Q14: 0.84583333
A15: TEMBALIHLE | B15: -29.74232619650293, 30.99327039689171 | C15: 0.23541667 | D15: 0.30486111 | F15: 0.47152778 | H15: 0.59652778 | J15: 0.67986111 | L15: 0.72152778 | N15: 0.77708333 | P15: 0.84652778
A16: kwaMASHU | B16: -29.750076129548816, 30.9736385977492 | C16: 0.23819444 | D16: 0.30763889 | F16: 0.47430556 | H16: 0.59930556 | J16: 0.68263889 | L16: 0.72430556 | N16: 0.77986111 | P16: 0.84930556
A17: BRIDGE CITY | B17: -29.726914572007956, 30.986441559931276 | E17: 0.31805556 | G17: 0.48472222 | I17: 0.60972222 | K17: 0.68541667 | M17: 0.72430556 | O17: 0.78055556 | Q17: 0.85

Sheet BRIDG-to-DURBN_Sat
A1: Last Updated: | B1: ='DURBN-to-BRIDG_Sat'!B1 -> 46076 | C1: ='DURBN-to-BRIDG_Weekday'!C1 -> Z2
A2: STATION | B2: COORDINATES | C2: 9324 | D2: 9724 | E2: 9344 | F2: 9732 | G2: 9364 | H2: 9736 | I2: 9374 | J2: 9748 | K2: 9404 | L2: 9758 | M2: 9424 | N2: 9762 | O2: 9434 | P2: 9776 | Q2: 9454
A3: BRIDGE CITY | B3: -29.726914572007956, 30.986441559931276 | D3: 0.24166667 | F3: 0.26944444 | H3: 0.30416667 | J3: 0.47083333 | L3: 0.59583333 | N3: 0.6375 | P3: 0.74166667
A4: kwaMASHU | B4: -29.750076129548816, 30.9736385977492 | C4: 0.20277778 | E4: 0.24444444 | G4: 0.27222222 | I4: 0.31388889 | K4: 0.48055556 | M4: 0.60555556 | O4: 0.64722222 | Q4: 0.74444444
A5: TEMBALIHLE | B5: -29.74232619650293, 30.99327039689171 | C5: 0.20486111 | E5: 0.24652778 | G5: 0.27430556 | I5: 0.31597222 | K5: 0.48263889 | M5: 0.60763889 | O5: 0.64930556 | Q5: 0.74652778
A6: DUFF'S ROAD | B6: -29.743381167737063, 31.00438746386499 | C6: 0.20833333 | D6: 0.24583333 | E6: 0.25 | F6: 0.27361111 | G6: 0.27777778 | H6: 0.30833333 | I6: 0.31944444 | J6: 0.475 | K6: 0.48611111 | L6: 0.6 | M6: 0.61111111 | N6: 0.64166667 | O6: 0.65277778 | P6: 0.74583333 | Q6: 0.75
A7: EFFINGHAM | B7: -29.771484689837905, 31.002467628997902
A8: KENVILLE | B8: -29.79223460755487, 31.00131508045099
A9: TEMPLE | B9: -29.803794322749017, 31.00594296514886
A10: AVOCA | B10: -29.760772221994845, 31.021557341565032 | C10: 0.21458333 | E10: 0.25625 | G10: 0.28402778 | I10: 0.32569444 | K10: 0.49236111 | M10: 0.61736111 | O10: 0.65902778 | Q10: 0.75625
A11: RED HILL | B11: -29.77881199269451, 31.02278786426192 | C11: 0.21805556 | E11: 0.25972222 | G11: 0.2875 | I11: 0.32916667 | K11: 0.49583333 | M11: 0.62083333 | O11: 0.6625 | Q11: 0.75972222
A12: GREENWOOD PARK | B12: -29.78886303102557, 31.019987033178655 | C12: 0.22083333 | E12: 0.2625 | G12: 0.29027778 | I12: 0.33194444 | K12: 0.49861111 | M12: 0.62361111 | O12: 0.66527778 | Q12: 0.7625
A13: BRIARDENE | B13: -29.796700991231464, 31.01418868183359 | C13: 0.22291667 | E13: 0.26458333 | G13: 0.29236111 | I13: 0.33402778 | K13: 0.50069444 | M13: 0.62569444 | O13: 0.66736111 | Q13: 0.76458333
A14: UMGENI | B14: -29.81680605847883, 31.02742038505348 | C14: 0.22777778 | E14: 0.26944444 | G14: 0.29722222 | I14: 0.33888889 | K14: 0.50555556 | M14: 0.63055556 | O14: 0.67222222 | Q14: 0.76944444
A15: MOSES MABHIDA | B15: -29.828174437586064, 31.03164291113771 | C15: 0.22916667 | E15: 0.27083333 | G15: 0.29861111 | I15: 0.34027778 | K15: 0.50694444 | M15: 0.63194444 | O15: 0.67361111 | Q15: 0.77083333
A16: DURBAN | B16: -29.84489056762199, 31.022357088460843 | C16: 0.23333333 | E16: 0.275 | G16: 0.30277778 | I16: 0.34444444 | K16: 0.51111111 | M16: 0.63611111 | O16: 0.67777778 | Q16: 0.775
A17: BEREA ROAD | B17: -29.85714656237288, 31.012251554171158 | C17: 0.23680556 | E17: 0.27847222 | G17: 0.30625 | I17: 0.34791667 | K17: 0.51458333 | M17: 0.63958333 | O17: 0.68125 | Q17: 0.77847222

Sheet DURBN-to-WINKL_Weekday
A1: Last Updated: | B1: 46230 | C1: Z2
A2: STATION | B2: COORDINATES | C2: 9006 | D2: 0708 | E2: 0712 | F2: 0716 | G2: 0720 | H2: 0724 | I2: 0728 | J2: 0732 | K2: 0738 | L2: 0744 | M2: 0750 | N2: 0756 | O2: 0762 | P2: 0768 | Q2: 0774 | R2: 0778 | S2: 0782 | T2: 0786 | U2: 0790
A3: DURBAN YARD | B3: -29.834333, 31.026139
A4: DURBAN | B4: -29.84489056762199, 31.022357088460843 | C4: 0.14583333 | D4: 0.15625 | E4: 0.17708333 | F4: 0.19791667 | G4: 0.21875 | H4: 0.23958333 | I4: 0.26041667 | J4: 0.28125 | K4: 0.32291667 | L4: 0.40625 | M4: 0.48958333 | N4: 0.57291667 | O4: 0.65625 | P4: 0.67708333 | Q4: 0.69791667 | R4: 0.71875 | S4: 0.73958333 | T4: 0.76041667 | U4: 0.78125
A5: BEREA ROAD | B5: -29.85714656237288, 31.012251554171158 | C5: 0.14861111 | D5: 0.15972222 | E5: 0.18055556 | F5: 0.20138889 | G5: 0.22222222 | H5: 0.24305556 | I5: 0.26388889 | J5: 0.28472222 | K5: 0.32638889 | L5: 0.40972222 | M5: 0.49305556 | N5: 0.57638889 | O5: 0.65972222 | P5: 0.68055556 | Q5: 0.70138889 | R5: 0.72222222 | S5: 0.74305556 | T5: 0.76388889 | U5: 0.78472222
A6: DALBRIDGE | B6: -29.868104078587393, 31.006295566319082 | C6: 0.15 | D6: 0.16180556 | E6: 0.18263889 | F6: 0.20347222 | G6: 0.22430556 | H6: 0.24513889 | I6: 0.26597222 | J6: 0.28680556 | K6: 0.32847222 | L6: 0.41180556 | M6: 0.49513889 | N6: 0.57847222 | O6: 0.66180556 | P6: 0.68263889 | Q6: 0.70347222 | R6: 0.72430556 | S6: 0.74513889 | T6: 0.76597222 | U6: 0.78680556
A7: CONGELLA | B7: -29.877807391239134, 30.99668920640153 | C7: 0.15347222 | D7: 0.16597222 | E7: 0.18680556 | F7: 0.20763889 | G7: 0.22847222 | H7: 0.24930556 | I7: 0.27013889 | J7: 0.29097222 | K7: 0.33263889 | L7: 0.41597222 | M7: 0.49930556 | N7: 0.58263889 | O7: 0.66597222 | P7: 0.68680556 | Q7: 0.70763889 | R7: 0.72847222 | S7: 0.74930556 | T7: 0.77013889 | U7: 0.79097222
A8: UMBILO | B8: -29.890435697363827, 30.984587874943184 | C8: 0.15625 | D8: 0.16944444 | E8: 0.19027778 | F8: 0.21111111 | G8: 0.23194444 | H8: 0.25277778 | I8: 0.27361111 | J8: 0.29444444 | K8: 0.33611111 | L8: 0.41944444 | M8: 0.50277778 | N8: 0.58611111 | O8: 0.66944444 | P8: 0.69027778 | Q8: 0.71111111 | R8: 0.73194444 | S8: 0.75277778 | T8: 0.77361111 | U8: 0.79444444
A9: ROSSBURGH | B9: -29.89940554926183, 30.980532514388575 | C9: 0.15833333 | D9: 0.17222222 | E9: 0.19305556 | F9: 0.21388889 | G9: 0.23472222 | H9: 0.25555556 | I9: 0.27638889 | J9: 0.29722222 | K9: 0.33888889 | L9: 0.42222222 | M9: 0.50555556 | N9: 0.58888889 | O9: 0.67222222 | P9: 0.69305556 | Q9: 0.71388889 | R9: 0.73472222 | S9: 0.75555556 | T9: 0.77638889 | U9: 0.79722222
A10: CLAIRWOOD | B10: -29.91586685921378, 30.976185952436662 | C10: 0.16319444 | D10: 0.17777778 | E10: 0.19861111 | F10: 0.21944444 | G10: 0.24027778 | H10: 0.26111111 | I10: 0.28194444 | J10: 0.30277778 | K10: 0.34444444 | L10: 0.42777778 | M10: 0.51111111 | N10: 0.59444444 | O10: 0.67777778 | P10: 0.69861111 | Q10: 0.71944444 | R10: 0.74027778 | S10: 0.76111111 | T10: 0.78194444 | U10: 0.80277778
A11: MONTCLAIR | B11: -29.925547602718428, 30.973277527535956 | C11: 0.16736111 | D11: 0.18263889 | E11: 0.20347222 | F11: 0.22430556 | G11: 0.24513889 | H11: 0.26597222 | I11: 0.28680556 | J11: 0.30763889 | K11: 0.34930556 | L11: 0.43263889 | M11: 0.51597222 | N11: 0.59930556 | O11: 0.68263889 | P11: 0.70347222 | Q11: 0.72430556 | R11: 0.74513889 | S11: 0.76597222 | T11: 0.78680556 | U11: 0.80763889
A12: MEREBANK | B12: -29.94387679464219, 30.95869476076833 | C12: 0.17013889 | D12: 0.1875 | E12: 0.20833333 | F12: 0.22916667 | G12: 0.25 | H12: 0.27083333 | I12: 0.29166667 | J12: 0.3125 | K12: 0.35416667 | L12: 0.4375 | M12: 0.52083333 | N12: 0.60416667 | O12: 0.6875 | P12: 0.70833333 | Q12: 0.72916667 | R12: 0.75 | S12: 0.77083333 | T12: 0.79166667 | U12: 0.8125
A13: REUNION | B13: -29.963257040786896, 30.941103712255764 | C13: 0.175 | D13: 0.19305556 | E13: 0.21388889 | F13: 0.23472222 | G13: 0.25555556 | H13: 0.27638889 | I13: 0.29722222 | J13: 0.31805556 | K13: 0.35972222 | L13: 0.44305556 | M13: 0.52638889 | N13: 0.60972222 | O13: 0.69305556 | P13: 0.71388889 | Q13: 0.73472222 | R13: 0.75555556 | S13: 0.77638889 | T13: 0.79722222 | U13: 0.81805556
A14: PELGRIM | B14: -29.974124952216233, 30.933854361876627 | C14: 0.17638889 | D14: 0.19513889 | E14: 0.21597222 | F14: 0.23680556 | G14: 0.25763889 | H14: 0.27847222 | I14: 0.29930556 | J14: 0.32013889 | K14: 0.36180556 | L14: 0.44513889 | M14: 0.52847222 | N14: 0.61180556 | O14: 0.69513889 | P14: 0.71597222 | Q14: 0.73680556 | R14: 0.75763889 | S14: 0.77847222 | T14: 0.79930556 | U14: 0.82013889
A15: ISIPINGO | B15: -29.98408153761452, 30.92863140522783 | C15: 0.17708333 | D15: 0.19791667 | E15: 0.21875 | F15: 0.23958333 | G15: 0.26041667 | H15: 0.28125 | I15: 0.30208333 | J15: 0.32291667 | K15: 0.36458333 | L15: 0.44791667 | M15: 0.53125 | N15: 0.61458333 | O15: 0.69791667 | P15: 0.71875 | Q15: 0.73958333 | R15: 0.76041667 | S15: 0.78125 | T15: 0.80208333 | U15: 0.82291667
... A21: WINKLESPRUIT | B21: -30.098583556349997, 30.856762947317485 | C21: 0.20347222 | D21: 0.22569444 | E21: 0.24652778 | F21: 0.26736111 | G21: 0.28819444 | H21: 0.30902778 | I21: 0.32986111 | J21: 0.35069444 | K21: 0.39236111 | L21: 0.47569444 | M21: 0.55902778 | N21: 0.64236111 | O21: 0.72569444 | P21: 0.74652778 | Q21: 0.76736111 | R21: 0.78819444 | S21: 0.80902778 | T21: 0.82986111 | U21: 0.85069444

Sheet WINKL-to-DURBN_Weekday
A1: Last Updated: | B1: ='DURBN-to-WINKL_Weekday'!B1 -> 46230 | C1: ='DURBN-to-WINKL_Weekday'!C1 -> Z2
A2: STATION | B2: COORDINATES | C2: 0711 | D2: 0715 | E2: 0719 | F2: 0723 | G2: 0727 | H2: 0731 | I2: 0735 | J2: 0739 | K2: 0743 | L2: 0749 | M2: 0755 | N2: 0761 | O2: 0767 | P2: 0773 | Q2: 0779 | R2: 0783 | S2: 0787 | T2: 0791
A3: WINKLESPRUIT | B3: -30.098583556349997, 30.856762947317485 | C3: 0.17013889 | D3: 0.19097222 | E3: 0.21180556 | F3: 0.23263889 | G3: 0.25347222 | H3: 0.27430556 | I3: 0.29513889 | J3: 0.31597222 | K3: 0.35763889 | L3: 0.39930556 | M3: 0.48263889 | N3: 0.56597222 | O3: 0.64930556 | P3: 0.69097222 | Q3: 0.73263889 | R3: 0.75347222 | S3: 0.77430556 | T3: 0.79513889
A4: WARNER BEACH | B4: -30.083787588048057, 30.867315491610743 | C4: 0.17222222 | D4: 0.19305556 | E4: 0.21388889 | F4: 0.23472222 | G4: 0.25555556 | H4: 0.27638889 | I4: 0.29722222 | J4: 0.31805556 | K4: 0.35972222 | L4: 0.40138889 | M4: 0.48472222 | N4: 0.56805556 | O4: 0.65138889 | P4: 0.69305556 | Q4: 0.73472222 | R4: 0.75555556 | S4: 0.77638889 | T4: 0.79722222
A5: DOONSIDE | B5: -30.07130309503173, 30.873493721739905 | C5: 0.17430556 | D5: 0.19513889 | E5: 0.21597222 | F5: 0.23680556 | G5: 0.25763889 | H5: 0.27847222 | I5: 0.29930556 | J5: 0.32013889 | K5: 0.36180556 | L5: 0.40347222 | M5: 0.48680556 | N5: 0.57013889 | O5: 0.65347222 | P5: 0.69513889 | Q5: 0.73680556 | R5: 0.75763889 | S5: 0.77847222 | T5: 0.79930556
A6: AMANZIMTOTI | B6: -30.056679072471063, 30.881613697740487 | C6: 0.17638889 | D6: 0.19722222 | E6: 0.21805556 | F6: 0.23888889 | G6: 0.25972222 | H6: 0.28055556 | I6: 0.30138889 | J6: 0.32222222 | K6: 0.36388889 | L6: 0.40555556 | M6: 0.48888889 | N6: 0.57222222 | O6: 0.65555556 | P6: 0.69722222 | Q6: 0.73888889 | R6: 0.75972222 | S6: 0.78055556 | T6: 0.80138889
A7: PAHLA | B7: -30.041351162488457, 30.889134409298176 | C7: 0.17916667 | D7: 0.2 | E7: 0.22083333 | F7: 0.24166667 | G7: 0.2625 | H7: 0.28333333 | I7: 0.30416667 | J7: 0.325 | K7: 0.36666667 | L7: 0.40833333 | M7: 0.49166667 | N7: 0.575 | O7: 0.65833333 | P7: 0.7 | Q7: 0.74166667 | R7: 0.7625 | S7: 0.78333333 | T7: 0.80416667
A8: UMBOGINTWINI | B8: -30.02251418559166, 30.907357309297154 | C8: 0.18333333 | D8: 0.20416667 | E8: 0.225 | F8: 0.24583333 | G8: 0.26666667 | H8: 0.2875 | I8: 0.30833333 | J8: 0.32916667 | K8: 0.37083333 | L8: 0.4125 | M8: 0.49583333 | N8: 0.57916667 | O8: 0.6625 | P8: 0.70416667 | Q8: 0.74583333 | R8: 0.76666667 | S8: 0.7875 | T8: 0.80833333
A9: ISIPINGO | B9: -29.98408153761452, 30.92863140522783 | C9: 0.19097222 | D9: 0.21180556 | E9: 0.23263889 | F9: 0.25347222 | G9: 0.27430556 | H9: 0.29513889 | I9: 0.31597222 | J9: 0.33680556 | K9: 0.37847222 | L9: 0.42013889 | M9: 0.50347222 | N9: 0.58680556 | O9: 0.67013889 | P9: 0.71180556 | Q9: 0.75347222 | R9: 0.77430556 | S9: 0.79513889 | T9: 0.81597222
A10: PELGRIM | B10: -29.974124952216233, 30.933854361876627 | C10: 0.19444444 | D10: 0.21527778 | E10: 0.23611111 | F10: 0.25694444 | G10: 0.27777778 | H10: 0.29861111 | I10: 0.31944444 | J10: 0.34027778 | K10: 0.38194444 | L10: 0.42361111 | M10: 0.50694444 | N10: 0.59027778 | O10: 0.67361111 | P10: 0.71527778 | Q10: 0.75694444 | R10: 0.77777778 | S10: 0.79861111 | T10: 0.81944444
A11: REUNION | B11: -29.963257040786896, 30.941103712255764 | C11: 0.19722222 | D11: 0.21805556 | E11: 0.23888889 | F11: 0.25972222 | G11: 0.28055556 | H11: 0.30138889 | I11: 0.32222222 | J11: 0.34305556 | K11: 0.38472222 | L11: 0.42638889 | M11: 0.50972222 | N11: 0.59305556 | O11: 0.67638889 | P11: 0.71805556 | Q11: 0.75972222 | R11: 0.78055556 | S11: 0.80138889 | T11: 0.82222222
A12: MEREBANK | B12: -29.94387679464219, 30.95869476076833 | C12: 0.20277778 | D12: 0.22361111 | E12: 0.24444444 | F12: 0.26527778 | G12: 0.28611111 | H12: 0.30694444 | I12: 0.32777778 | J12: 0.34861111 | K12: 0.39027778 | L12: 0.43194444 | M12: 0.51527778 | N12: 0.59861111 | O12: 0.68194444 | P12: 0.72361111 | Q12: 0.76527778 | R12: 0.78611111 | S12: 0.80694444 | T12: 0.82777778
A13: MONTCLAIR | B13: -29.925547602718428, 30.973277527535956 | C13: 0.20625 | D13: 0.22708333 | E13: 0.24791667 | F13: 0.26875 | G13: 0.28958333 | H13: 0.31041667 | I13: 0.33125 | J13: 0.35208333 | K13: 0.39375 | L13: 0.43541667 | M13: 0.51875 | N13: 0.60208333 | O13: 0.68541667 | P13: 0.72708333 | Q13: 0.76875 | R13: 0.78958333 | S13: 0.81041667 | T13: 0.83125
A14: CLAIRWOOD | B14: -29.91586685921378, 30.976185952436662 | C14: 0.21111111 | D14: 0.23194444 | E14: 0.25277778 | F14: 0.27361111 | G14: 0.29444444 | H14: 0.31527778 | I14: 0.33611111 | J14: 0.35694444 | K14: 0.39861111 | L14: 0.44027778 | M14: 0.52361111 | N14: 0.60694444 | O14: 0.69027778 | P14: 0.73194444 | Q14: 0.77361111 | R14: 0.79444444 | S14: 0.81527778 | T14: 0.83611111
... A20: DURBAN | B20: -29.84489056762199, 31.022357088460843 | C20: 0.23333333 | D20: 0.25416667 | E20: 0.275 | F20: 0.29583333 | G20: 0.31666667 | H20: 0.3375 | I20: 0.35833333 | J20: 0.37916667 | K20: 0.42083333 | L20: 0.4625 | M20: 0.54583333 | N20: 0.62916667 | O20: 0.7125 | P20: 0.75416667 | Q20: 0.79583333 | R20: 0.81666667 | S20: 0.8375 | T20: 0.85833333
A21: DURBAN YARD | B21: -29.834333, 31.026139

Sheet DURBN-to-WINKL_Sat
A1: Last Updated: | B1: 46230 | C1: ='DURBN-to-WINKL_Weekday'!C1 -> Z2
A2: STATION | B2: COORDINATES | C2: 712 | D2: 720 | E2: 728 | F2: 738 | G2: 756 | H2: 768 | I2: 778 | J2: 790
A3: DURBAN YARD | B3: -29.834333, 31.026139
A4: DURBAN | B4: -29.84489056762199, 31.022357088460843 | C4: 0.17708333 | D4: 0.21875 | E4: 0.26041667 | F4: 0.32291667 | G4: 0.57291667 | H4: 0.65625 | I4: 0.71875 | J4: 0.78125
A5: BEREA ROAD | B5: -29.85714656237288, 31.012251554171158 | C5: 0.18055556 | D5: =D4+C5-C4 -> 0.22222222 | E5: =E4+D5-D4 -> 0.26388889 | F5: =F4+E5-E4 -> 0.32638889 | G5: =G4+F5-F4 -> 0.57638889 | H5: =H4+G5-G4 -> 0.65972222 | I5: =I4+H5-H4 -> 0.72222222 | J5: =J4+I5-I4 -> 0.78472222
A6: DALBRIDGE | B6: -29.868104078587393, 31.006295566319082 | C6: 0.18263889 | D6: =D5+C6-C5 -> 0.22430556 | E6: =E5+D6-D5 -> 0.26597222 | F6: =F5+E6-E5 -> 0.32847222 | G6: =G5+F6-F5 -> 0.57847222 | H6: =H5+G6-G5 -> 0.66180556 | I6: =I5+H6-H5 -> 0.72430556 | J6: =J5+I6-I5 -> 0.78680556
A7: CONGELLA | B7: -29.877807391239134, 30.99668920640153 | C7: 0.18680556 | D7: =D6+C7-C6 -> 0.22847222 | E7: =E6+D7-D6 -> 0.27013889 | F7: =F6+E7-E6 -> 0.33263889 | G7: =G6+F7-F6 -> 0.58263889 | H7: =H6+G7-G6 -> 0.66597222 | I7: =I6+H7-H6 -> 0.72847222 | J7: =J6+I7-I6 -> 0.79097222
A8: UMBILO | B8: -29.890435697363827, 30.984587874943184 | C8: 0.19027778 | D8: =D7+C8-C7 -> 0.23194444 | E8: =E7+D8-D7 -> 0.27361111 | F8: =F7+E8-E7 -> 0.33611111 | G8: =G7+F8-F7 -> 0.58611111 | H8: =H7+G8-G7 -> 0.66944444 | I8: =I7+H8-H7 -> 0.73194444 | J8: =J7+I8-I7 -> 0.79444444
A9: ROSSBURGH | B9: -29.89940554926183, 30.980532514388575 | C9: 0.19305556 | D9: =D8+C9-C8 -> 0.23472222 | E9: =E8+D9-D8 -> 0.27638889 | F9: =F8+E9-E8 -> 0.33888889 | G9: =G8+F9-F8 -> 0.58888889 | H9: =H8+G9-G8 -> 0.67222222 | I9: =I8+H9-H8 -> 0.73472222 | J9: =J8+I9-I8 -> 0.79722222
A10: CLAIRWOOD | B10: -29.91586685921378, 30.976185952436662 | C10: 0.19861111 | D10: =D9+C10-C9 -> 0.24027778 | E10: =E9+D10-D9 -> 0.28194444 | F10: =F9+E10-E9 -> 0.34444444 | G10: =G9+F10-F9 -> 0.59444444 | H10: =H9+G10-G9 -> 0.67777778 | I10: =I9+H10-H9 -> 0.74027778 | J10: =J9+I10-I9 -> 0.80277778
A11: MONTCLAIR | B11: -29.925547602718428, 30.973277527535956 | C11: 0.20347222 | D11: =D10+C11-C10 -> 0.24513889 | E11: =E10+D11-D10 -> 0.28680556 | F11: =F10+E11-E10 -> 0.34930556 | G11: =G10+F11-F10 -> 0.59930556 | H11: =H10+G11-G10 -> 0.68263889 | I11: =I10+H11-H10 -> 0.74513889 | J11: =J10+I11-I10 -> 0.80763889
A12: MEREBANK | B12: -29.94387679464219, 30.95869476076833 | C12: 0.20833333 | D12: =D11+C12-C11 -> 0.25 | E12: =E11+D12-D11 -> 0.29166667 | F12: =F11+E12-E11 -> 0.35416667 | G12: =G11+F12-F11 -> 0.60416667 | H12: =H11+G12-G11 -> 0.6875 | I12: =I11+H12-H11 -> 0.75 | J12: =J11+I12-I11 -> 0.8125
A13: REUNION | B13: -29.963257040786896, 30.941103712255764 | C13: 0.21388889 | D13: =D12+C13-C12 -> 0.25555556 | E13: =E12+D13-D12 -> 0.29722222 | F13: =F12+E13-E12 -> 0.35972222 | G13: =G12+F13-F12 -> 0.60972222 | H13: =H12+G13-G12 -> 0.69305556 | I13: =I12+H13-H12 -> 0.75555556 | J13: =J12+I13-I12 -> 0.81805556
A14: PELGRIM | B14: -29.974124952216233, 30.933854361876627 | C14: 0.21597222 | D14: =D13+C14-C13 -> 0.25763889 | E14: =E13+D14-D13 -> 0.29930556 | F14: =F13+E14-E13 -> 0.36180556 | G14: =G13+F14-F13 -> 0.61180556 | H14: =H13+G14-G13 -> 0.69513889 | I14: =I13+H14-H13 -> 0.75763889 | J14: =J13+I14-I13 -> 0.82013889
A15: ISIPINGO | B15: -29.98408153761452, 30.92863140522783 | C15: 0.21875 | D15: =D14+C15-C14 -> 0.26041667 | E15: =E14+D15-D14 -> 0.30208333 | F15: =F14+E15-E14 -> 0.36458333 | G15: =G14+F15-F14 -> 0.61458333 | H15: =H14+G15-G14 -> 0.69791667 | I15: =I14+H15-H14 -> 0.76041667 | J15: =J14+I15-I14 -> 0.82291667
A16: UMBOGINTWINI | B16: -30.02251418559166, 30.907357309297154 | C16: 0.225 | D16: =D15+C16-C15 -> 0.26666667 | E16: =E15+D16-D15 -> 0.30833333 | F16: =F15+E16-E15 -> 0.37083333 | G16: =G15+F16-F15 -> 0.62083333 | H16: =H15+G16-G15 -> 0.70416667 | I16: =I15+H16-H15 -> 0.76666667 | J16: =J15+I16-I15 -> 0.82916667
... A21: WINKLESPRUIT | B21: -30.098583556349997, 30.856762947317485 | C21: 0.24652778 | D21: =D20+C21-C20 -> 0.28819444 | E21: =E20+D21-D20 -> 0.32986111 | F21: =F20+E21-E20 -> 0.39236111 | G21: =G20+F21-F20 -> 0.64236111 | H21: =H20+G21-G20 -> 0.72569444 | I21: =I20+H21-H20 -> 0.78819444 | J21: =J20+I21-I20 -> 0.85069444

Sheet WINKL-to-DURBN_Sat
A1: Last Updated: | B1: 46230 | C1: ='DURBN-to-WINKL_Weekday'!C1 -> Z2
A2: STATION | B2: COORDINATES | C2: 711 | D2: 715 | E2: 727 | F2: 735 | G2: 743 | H2: 761 | I2: 767 | J2: 779
A3: WINKLESPRUIT | B3: -30.098583556349997, 30.856762947317485 | C3: 0.17013889 | D3: 0.19097222 | E3: 0.25347222 | F3: 0.29513889 | G3: 0.35763889 | H3: 0.56597222 | I3: 0.64930556 | J3: 0.73263889
A4: WARNER BEACH | B4: -30.083787588048057, 30.867315491610743 | C4: 0.17222222 | D4: =D3+C4-C3 -> 0.19305556 | E4: =E3+D4-D3 -> 0.25555556 | F4: =F3+E4-E3 -> 0.29722222 | G4: =G3+F4-F3 -> 0.35972222 | H4: =H3+G4-G3 -> 0.56805556 | I4: =I3+H4-H3 -> 0.65138889 | J4: =J3+I4-I3 -> 0.73472222
A5: DOONSIDE | B5: -30.07130309503173, 30.873493721739905 | C5: 0.17430556 | D5: =D4+C5-C4 -> 0.19513889 | E5: =E4+D5-D4 -> 0.25763889 | F5: =F4+E5-E4 -> 0.29930556 | G5: =G4+F5-F4 -> 0.36180556 | H5: =H4+G5-G4 -> 0.57013889 | I5: =I4+H5-H4 -> 0.65347222 | J5: =J4+I5-I4 -> 0.73680556
A6: AMANZIMTOTI | B6: -30.056679072471063, 30.881613697740487 | C6: 0.17638889 | D6: =D5+C6-C5 -> 0.19722222 | E6: =E5+D6-D5 -> 0.25972222 | F6: =F5+E6-E5 -> 0.30138889 | G6: =G5+F6-F5 -> 0.36388889 | H6: =H5+G6-G5 -> 0.57222222 | I6: =I5+H6-H5 -> 0.65555556 | J6: =J5+I6-I5 -> 0.73888889
A7: PAHLA | B7: -30.041351162488457, 30.889134409298176 | C7: 0.17916667 | D7: =D6+C7-C6 -> 0.2 | E7: =E6+D7-D6 -> 0.2625 | F7: =F6+E7-E6 -> 0.30416667 | G7: =G6+F7-F6 -> 0.36666667 | H7: =H6+G7-G6 -> 0.575 | I7: =I6+H7-H6 -> 0.65833333 | J7: =J6+I7-I6 -> 0.74166667
A8: UMBOGINTWINI | B8: -30.02251418559166, 30.907357309297154 | C8: 0.18333333 | D8: =D7+C8-C7 -> 0.20416667 | E8: =E7+D8-D7 -> 0.26666667 | F8: =F7+E8-E7 -> 0.30833333 | G8: =G7+F8-F7 -> 0.37083333 | H8: =H7+G8-G7 -> 0.57916667 | I8: =I7+H8-H7 -> 0.6625 | J8: =J7+I8-I7 -> 0.74583333
A9: ISIPINGO | B9: -29.98408153761452, 30.92863140522783 | C9: 0.19097222 | D9: =D8+C9-C8 -> 0.21180556 | E9: =E8+D9-D8 -> 0.27430556 | F9: =F8+E9-E8 -> 0.31597222 | G9: =G8+F9-F8 -> 0.37847222 | H9: =H8+G9-G8 -> 0.58680556 | I9: =I8+H9-H8 -> 0.67013889 | J9: =J8+I9-I8 -> 0.75347222
A10: PELGRIM | B10: -29.974124952216233, 30.933854361876627 | C10: 0.19444444 | D10: =D9+C10-C9 -> 0.21527778 | E10: =E9+D10-D9 -> 0.27777778 | F10: =F9+E10-E9 -> 0.31944444 | G10: =G9+F10-F9 -> 0.38194444 | H10: =H9+G10-G9 -> 0.59027778 | I10: =I9+H10-H9 -> 0.67361111 | J10: =J9+I10-I9 -> 0.75694444
A11: REUNION | B11: -29.963257040786896, 30.941103712255764 | C11: 0.19722222 | D11: =D10+C11-C10 -> 0.21805556 | E11: =E10+D11-D10 -> 0.28055556 | F11: =F10+E11-E10 -> 0.32222222 | G11: =G10+F11-F10 -> 0.38472222 | H11: =H10+G11-G10 -> 0.59305556 | I11: =I10+H11-H10 -> 0.67638889 | J11: =J10+I11-I10 -> 0.75972222
A12: MEREBANK | B12: -29.94387679464219, 30.95869476076833 | C12: 0.20277778 | D12: =D11+C12-C11 -> 0.22361111 | E12: =E11+D12-D11 -> 0.28611111 | F12: =F11+E12-E11 -> 0.32777778 | G12: =G11+F12-F11 -> 0.39027778 | H12: =H11+G12-G11 -> 0.59861111 | I12: =I11+H12-H11 -> 0.68194444 | J12: =J11+I12-I11 -> 0.76527778
