Workbook

Sheet ABC-to-ABC_Weekday
A1: Last Updated: | B1: 45345 | C1: Z1 | D1: =SORT(A2:A14, ROW(A2:A14), 0)
A2: STATION | B2: COORDINATES | C2: 4400 | D2: 4402 | E2: 4420
A3: DE WILDT | B3: -25.624641315648187, 27.944111334913465 | C3: 0.19444444 | D3: 0.3125 | E3: 0.68402778
A4: TAILLARDSHOOP | B4: -25.617806769500547, 27.972401220150644 | C4: 0.19791667 | D4: 0.31597222 | E4: 0.6875
A5: GA-RANKUWA | B5: -25.619463521827942, 27.991787773598496 | C5: 0.2 | D5: 0.31805556 | E5: 0.68958333
A6: ROSSLYN | B6: -25.637700722357806, 28.094920182723996 | C6: 0.20833333 | D6: 0.32638889 | E6: 0.69791667
A7: WINTERSNEST | B7: -25.646665143468105, 28.128664081235527 | C7: 0.21180556 | D7: 0.32986111 | E7: 0.70138889
A8: WOLMERTON | B8: -25.656754583256834, 28.166308537943245 | C8: 0.21597222 | D8: 0.33402778 | E8: 0.70555556
A9: PRETORIA-N | B9: -25.672156912459837, 28.181972182122085 | C9: 0.21875 | D9: 0.33680556 | E9: 0.70833333
A10: MOUNTAIN VIEW | B10: -25.701154966265122, 28.1710407244521 | C10: 0.22361111 | D10: 0.34166667 | E10: 0.71319444
A11: HERCULES | B11: -25.724426332570793, 28.16740145328856 | C11: 0.22708333 | D11: 0.34513889 | E11: 0.71666667
A12: PRETORIA WES | B12: -25.75612607001734, 28.167454033423436 | C12: 0.23194444 | D12: 0.35 | E12: 0.72152778
A13: PRETORIA | B13: -25.75864361043285, 28.189866445989118 | C13: 0.23611111 | D13: 0.35416667 | E13: 0.72569444

Sheet Archive_2025

Sheet EVENT-to-A_Weekday
A1: Last Updated: | B1: 45345 | C1: Z1 | D1: =SORT(A2:A14, ROW(A2:A14), 0)
A2: STATION | B2: COORDINATES | C2: 4400 | D2: 4402 | E2: 4420
A3: DE WILDT | B3: -25.624641315648187, 27.944111334913465 | C3: 0.19444444 | D3: 0.3125 | E3: 0.68402778
A4: TAILLARDSHOOP | B4: -25.617806769500547, 27.972401220150644 | C4: 0.19791667 | D4: 0.31597222 | E4: 0.6875
A5: GA-RANKUWA | B5: -25.619463521827942, 27.991787773598496 | C5: 0.2 | D5: 0.31805556 | E5: 0.68958333
A6: ROSSLYN | B6: -25.637700722357806, 28.094920182723996 | C6: 0.20833333 | D6: 0.32638889 | E6: 0.69791667
A7: WINTERSNEST | B7: -25.646665143468105, 28.128664081235527 | C7: 0.21180556 | D7: 0.32986111 | E7: 0.70138889
A8: WOLMERTON | B8: -25.656754583256834, 28.166308537943245 | C8: 0.21597222 | D8: 0.33402778 | E8: 0.70555556
A9: PRETORIA-N | B9: -25.672156912459837, 28.181972182122085 | C9: 0.21875 | D9: 0.33680556 | E9: 0.70833333
A10: MOUNTAIN VIEW | B10: -25.701154966265122, 28.1710407244521 | C10: 0.22361111 | D10: 0.34166667 | E10: 0.71319444
A11: HERCULES | B11: -25.724426332570793, 28.16740145328856 | C11: 0.22708333 | D11: 0.34513889 | E11: 0.71666667
A12: PRETORIA WES | B12: -25.75612607001734, 28.167454033423436 | C12: 0.23194444 | D12: 0.35 | E12: 0.72152778
A13: PRETORIA | B13: -25.75864361043285, 28.189866445989118 | C13: 0.23611111 | D13: 0.35416667 | E13: 0.72569444

Sheet EVENT-to-B_Weekday
A1: Last Updated: | B1: 45345 | C1: Z1 | D1: =SORT(A2:A14, ROW(A2:A14), 0)
A2: STATION | B2: COORDINATES | C2: 4400 | D2: 4402 | E2: 4420
A3: DE WILDT | B3: -25.624641315648187, 27.944111334913465 | C3: 0.19444444 | D3: 0.3125 | E3: 0.68402778
A4: TAILLARDSHOOP | B4: -25.617806769500547, 27.972401220150644 | C4: 0.19791667 | D4: 0.31597222 | E4: 0.6875
A5: GA-RANKUWA | B5: -25.619463521827942, 27.991787773598496 | C5: 0.2 | D5: 0.31805556 | E5: 0.68958333
A6: ROSSLYN | B6: -25.637700722357806, 28.094920182723996 | C6: 0.20833333 | D6: 0.32638889 | E6: 0.69791667
A7: WINTERSNEST | B7: -25.646665143468105, 28.128664081235527 | C7: 0.21180556 | D7: 0.32986111 | E7: 0.70138889
A8: WOLMERTON | B8: -25.656754583256834, 28.166308537943245 | C8: 0.21597222 | D8: 0.33402778 | E8: 0.70555556
A9: PRETORIA-N | B9: -25.672156912459837, 28.181972182122085 | C9: 0.21875 | D9: 0.33680556 | E9: 0.70833333
A10: MOUNTAIN VIEW | B10: -25.701154966265122, 28.1710407244521 | C10: 0.22361111 | D10: 0.34166667 | E10: 0.71319444
A11: HERCULES | B11: -25.724426332570793, 28.16740145328856 | C11: 0.22708333 | D11: 0.34513889 | E11: 0.71666667
A12: PRETORIA WES | B12: -25.75612607001734, 28.167454033423436 | C12: 0.23194444 | D12: 0.35 | E12: 0.72152778
A13: PRETORIA | B13: -25.75864361043285, 28.189866445989118 | C13: 0.23611111 | D13: 0.35416667 | E13: 0.72569444

Sheet EVENT-to-A_Sat
A1: Last Updated: | B1: 45345 | C1: Z1 | D1: =SORT(A2:A14, ROW(A2:A14), 0)
A2: STATION | B2: COORDINATES | C2: 4400 | D2: 4402 | E2: 4420
A3: DE WILDT | B3: -25.624641315648187, 27.944111334913465 | C3: 0.19444444 | D3: 0.3125 | E3: 0.68402778
A4: TAILLARDSHOOP | B4: -25.617806769500547, 27.972401220150644 | C4: 0.19791667 | D4: 0.31597222 | E4: 0.6875
A5: GA-RANKUWA | B5: -25.619463521827942, 27.991787773598496 | C5: 0.2 | D5: 0.31805556 | E5: 0.68958333
A6: ROSSLYN | B6: -25.637700722357806, 28.094920182723996 | C6: 0.20833333 | D6: 0.32638889 | E6: 0.69791667
A7: WINTERSNEST | B7: -25.646665143468105, 28.128664081235527 | C7: 0.21180556 | D7: 0.32986111 | E7: 0.70138889
A8: WOLMERTON | B8: -25.656754583256834, 28.166308537943245 | C8: 0.21597222 | D8: 0.33402778 | E8: 0.70555556
A9: PRETORIA-N | B9: -25.672156912459837, 28.181972182122085 | C9: 0.21875 | D9: 0.33680556 | E9: 0.70833333
A10: MOUNTAIN VIEW | B10: -25.701154966265122, 28.1710407244521 | C10: 0.22361111 | D10: 0.34166667 | E10: 0.71319444
A11: HERCULES | B11: -25.724426332570793, 28.16740145328856 | C11: 0.22708333 | D11: 0.34513889 | E11: 0.71666667
A12: PRETORIA WES | B12: -25.75612607001734, 28.167454033423436 | C12: 0.23194444 | D12: 0.35 | E12: 0.72152778
A13: PRETORIA | B13: -25.75864361043285, 28.189866445989118 | C13: 0.23611111 | D13: 0.35416667 | E13: 0.72569444

Sheet EVENT-to-B_Sat
A1: Last Updated: | B1: 45345 | C1: Z1 | D1: =SORT(A2:A14, ROW(A2:A14), 0)
A2: STATION | B2: COORDINATES | C2: 4400 | D2: 4402 | E2: 4420
A3: DE WILDT | B3: -25.624641315648187, 27.944111334913465 | C3: 0.19444444 | D3: 0.3125 | E3: 0.68402778
A4: TAILLARDSHOOP | B4: -25.617806769500547, 27.972401220150644 | C4: 0.19791667 | D4: 0.31597222 | E4: 0.6875
A5: GA-RANKUWA | B5: -25.619463521827942, 27.991787773598496 | C5: 0.2 | D5: 0.31805556 | E5: 0.68958333
A6: ROSSLYN | B6: -25.637700722357806, 28.094920182723996 | C6: 0.20833333 | D6: 0.32638889 | E6: 0.69791667
A7: WINTERSNEST | B7: -25.646665143468105, 28.128664081235527 | C7: 0.21180556 | D7: 0.32986111 | E7: 0.70138889
A8: WOLMERTON | B8: -25.656754583256834, 28.166308537943245 | C8: 0.21597222 | D8: 0.33402778 | E8: 0.70555556
A9: PRETORIA-N | B9: -25.672156912459837, 28.181972182122085 | C9: 0.21875 | D9: 0.33680556 | E9: 0.70833333
A10: MOUNTAIN VIEW | B10: -25.701154966265122, 28.1710407244521 | C10: 0.22361111 | D10: 0.34166667 | E10: 0.71319444
A11: HERCULES | B11: -25.724426332570793, 28.16740145328856 | C11: 0.22708333 | D11: 0.34513889 | E11: 0.71666667
A12: PRETORIA WES | B12: -25.75612607001734, 28.167454033423436 | C12: 0.23194444 | D12: 0.35 | E12: 0.72152778
A13: PRETORIA | B13: -25.75864361043285, 28.189866445989118 | C13: 0.23611111 | D13: 0.35416667 | E13: 0.72569444

Sheet UNCLASSIFIED_TRAINS
A1: Last Updated: | B1: ='CT-to-MALM_Weekday'!B1 -> 46181
A2: STATION | B2: COORDINATES

Sheet CEN_IN_WK_MASTER
A1: Last Updated: | B1: Unspecified | C1: Z1
A2: STATION | B2: COORDINATES | C2: 9400 | D2: 9500 | E2: 9900 | F2: 9402 | G2: 9002 | H2: 9502 | I2: 9420 | J2: 9004 | K2: 9902 | L2: 9006 | M2: 9404 | N2: 9504 | O2: 9904 | P2: 9406 | Q2: 9506 | R2: 9008 | S2: 9906 | T2: 9010 | U2: 9408 | V2: 9508 | W2: 9012 | X2: 9908 | Y2: 9510 | Z2: 9014 | AA2: 9910 | AB2: 9016 | AC2: 9410 | AD2: 9018 | AE2: 9912 | AF2: 9512 | AG2: 9020 | AH2: 9412 | AI2: 9514 | AJ2: 9022 | AK2: 9914 | AL2: 9024 | AM2: 9916 | AN2: 9516 | AO2: 9414 | AP2: 9026 | AQ2: 9918 | AR2: 9518 | AS2: 9028 | AT2: 9416 | AU2: 9520 | AV2: 9920 | AW2: 9522
A3: BELLVILLE | B3: -33.906263459762684, 18.62662128465745 | G3: 0.23263889 | J3: 0.26041667 | L3: 0.29513889 | R3: 0.35763889 | T3: 0.38194444 | W3: 0.43402778 | Z3: 0.49305556 | AB3: 0.53472222 | AD3: 0.55208333 | AG3: 0.61458333 | AJ3: 0.65277778 | AL3: 0.68402778 | AP3: 0.73611111 | AS3: 0.76388889
A4: SAREPTA | B4: -33.92655594121331, 18.661143180651308 | G4: 0.23680556 | J4: 0.26458333 | L4: 0.29930556 | R4: 0.36180556 | T4: 0.38611111 | W4: 0.43819444 | Z4: 0.49722222 | AB4: 0.53888889 | AD4: 0.55625 | AG4: 0.61875 | AJ4: 0.65694444 | AL4: 0.68819444 | AP4: 0.74027778 | AS4: 0.76805556
A5: PENTECH | B5: -33.93468015167005, 18.646053668734744 | G5: 0.23888889 | J5: 0.26666667 | L5: 0.30138889 | R5: 0.36388889 | T5: 0.38819444 | W5: 0.44027778 | Z5: 0.49930556 | AB5: 0.54097222 | AD5: 0.55833333 | AG5: 0.62083333 | AJ5: 0.65902778 | AL5: 0.69027778 | AP5: 0.74236111 | AS5: 0.77013889
A6: UNIBELL | B6: -33.93686354314193, 18.628117540172582 | G6: 0.24166667 | J6: 0.26944444 | L6: 0.30416667 | R6: 0.36666667 | T6: 0.39097222 | W6: 0.44305556 | Z6: 0.50208333 | AB6: 0.54375 | AD6: 0.56111111 | AG6: 0.62361111 | AJ6: 0.66180556 | AL6: 0.69305556 | AP6: 0.74513889 | AS6: 0.77291667
A7: BELHAR | B7: -33.93959717971092, 18.60894476900841 | G7: 0.24444444 | J7: 0.27222222 | L7: 0.30694444 | R7: 0.36944444 | T7: 0.39375 | W7: 0.44583333 | Z7: 0.50486111 | AB7: 0.54652778 | AD7: 0.56388889 | AG7: 0.62638889 | AJ7: 0.66458333 | AL7: 0.69583333 | AP7: 0.74791667 | AS7: 0.77569444
A8: LAVISTOWN | B8: -33.943269567798055, 18.583722311337315 | G8: 0.24652778 | J8: 0.27430556 | L8: 0.30902778 | R8: 0.37152778 | T8: 0.39583333 | W8: 0.44791667 | Z8: 0.50694444 | AB8: 0.54861111 | AD8: 0.56597222 | AG8: 0.62847222 | AJ8: 0.66666667 | AL8: 0.69791667 | AP8: 0.75 | AS8: 0.77777778
A9: CHRIS HANI | B9: -34.054706073305944, 18.710707924836054 | E9: 0.20486111 | K9: 0.25833333 | O9: 0.3125 | S9: 0.3625 | X9: 0.43194444 | AA9: 0.48958333 | AE9: 0.54861111 | AK9: 0.62638889 | AM9: 0.68402778 | AQ9: 0.73611111 | AV9: 0.79861111
A10: KUYASA | B10: -34.05489939537871, 18.692323957717754 | E10: 0.20763889 | K10: 0.26111111 | O10: 0.31527778 | S10: 0.36527778 | X10: 0.43472222 | AA10: 0.49236111 | AE10: 0.55138889 | AK10: 0.62916667 | AM10: 0.68680556 | AQ10: 0.73888889 | AV10: 0.80138889
A11: KHAYELITSHA | B11: -34.047943373751565, 18.67073769040669 | E11: 0.20972222 | K11: 0.26319444 | O11: 0.31736111 | S11: 0.36736111 | X11: 0.43680556 | AA11: 0.49444444 | AE11: 0.55347222 | AK11: 0.63125 | AM11: 0.68888889 | AQ11: 0.74097222 | AV11: 0.80347222
A12: NONKQUBELA | B12: -34.02681746271161, 18.663190611341626 | E12: 0.2125 | K12: 0.26597222 | O12: 0.32013889 | S12: 0.37013889 | X12: 0.43958333 | AA12: 0.49722222 | AE12: 0.55625 | AK12: 0.63402778 | AM12: 0.69166667 | AQ12: 0.74375 | AV12: 0.80625
A13: NOLUNGILE | B13: -34.016811809063164, 18.64902361716287 | C13: 0.19444444 | E13: 0.21527778 | F13: 0.22569444 | I13: 0.25763889 | K13: 0.26875 | M13: 0.30069444 | O13: 0.32291667 | P13: 0.34722222 | S13: 0.37291667 | U13: 0.39722222 | X13: 0.44236111 | AA13: 0.5 | AC13: 0.54513889 | AE13: 0.55902778 | AH13: 0.63888889 | AK13: 0.63680556 | AM13: 0.69444444 | AO13: 0.70833333 | AQ13: 0.74652778 | AT13: 0.77222222 | AV13: 0.80902778
A14: MANDALAY | B14: -34.019015667481014, 18.624391145998562 | C14: 0.19722222 | E14: 0.21805556 | F14: 0.22847222 | I14: 0.26041667 | K14: 0.27152778 | M14: 0.30347222 | O14: 0.32569444 | P14: 0.35 | S14: 0.37569444 | U14: 0.4 | X14: 0.44513889 | AA14: 0.50277778 | AC14: 0.54791667 | AE14: 0.56180556 | AH14: 0.64166667 | AK14: 0.63958333 | AM14: 0.69722222 | AO14: 0.71111111 | AQ14: 0.74930556 | AT14: 0.775 | AV14: 0.81180556
A15: STOCK ROAD | B15: -34.01412292128464, 18.606174209491407 | C15: 0.19930556 | E15: 0.22013889 | F15: 0.23055556 | I15: 0.2625 | K15: 0.27361111 | M15: 0.30555556 | O15: 0.32777778 | P15: 0.35208333 | S15: 0.37777778 | U15: 0.40208333 | X15: 0.44722222 | AA15: 0.50486111 | AC15: 0.55 | AE15: 0.56388889 | AH15: 0.64375 | AK15: 0.64166667 | AM15: 0.69930556 | AO15: 0.71319444 | AQ15: 0.75138889 | AT15: 0.77708333 | AV15: 0.81388889
A16: KAPTEINSKLIP | B16: -34.06755873543257, 18.620534480658506 | D16: 0.19444444 | H16: 0.24652778 | N16: 0.29861111 | Q16: 0.34722222 | U16: 0.39583333 | Y16: 0.45138889 | AF16: 0.55555556 | AI16: 0.64930556 | AN16: 0.69930556 | AR16: 0.75208333 | AU16: 0.79513889 | AW16: 0.82986111
A17: MITCHELL'S PLAIN | B17: -34.0504610838304, 18.619222253671435 | D17: 0.2 | H17: 0.25208333 | N17: 0.30416667 | Q17: 0.35277778 | U17: 0.40138889 | Y17: 0.45694444 | AF17: 0.56111111 | AI17: 0.65486111 | AN17: 0.70486111 | AR17: 0.75763889 | AU17: 0.80069444 | AW17: 0.83194444
A18: LENTEGEUR | B18: -34.03418971685345, 18.611322738328173 | D18: 0.20486111 | N18: 0.30902778 | Q18: 0.35763889 | U18: 0.40625 | Y18: 0.46180556 | AF18: 0.56597222 | AI18: 0.65972222 | AN18: 0.70972222 | AR18: 0.7625 | AU18: 0.80555556 | AW18: 0.83333333
A19: PHILIPPI | B19: -34.01328895709482, 18.584421561340882 | C19: 0.20277778 | D19: 0.20833333 | E19: 0.22361111 | F19: 0.23402778 | H19: 0.26041667 | I19: 0.26597222 | K19: 0.27708333 | M19: 0.30902778 | N19: 0.3125 | O19: 0.33125 | P19: 0.35555556 | Q19: 0.36111111 | S19: 0.38125 | U19: 0.40555556 | V19: 0.40972222 | X19: 0.45069444 | Y19: 0.46527778 | AA19: 0.50833333 | AC19: 0.55347222 | AE19: 0.56736111 | AF19: 0.56944444 | AH19: 0.64722222 | AI19: 0.66319444 | AK19: 0.64513889 | AM19: 0.70277778 | AN19: 0.71319444 | AO19: 0.71666667 | AQ19: 0.75486111 | AR19: 0.76597222 | AT19: 0.78055556 | AU19: 0.80902778 | AV19: 0.81736111 | AW19: 0.83680556
A20: NYANGA | B20: -33.99271379632963, 18.559776951819032 | C20: 0.20555556 | D20: 0.21111111 | E20: 0.22638889 | F20: 0.23680556 | H20: 0.26319444 | I20: 0.26875 | K20: 0.27986111 | M20: 0.31180556 | N20: 0.31527778 | O20: 0.33402778 | P20: 0.35833333 | Q20: 0.36388889 | S20: 0.38402778 | U20: 0.40833333 | V20: 0.4125 | X20: 0.45347222 | Y20: 0.46805556 | AA20: 0.51111111 | AC20: 0.55625 | AE20: 0.57013889 | AF20: 0.57222222 | AH20: 0.65 | AI20: 0.66597222 | AK20: 0.64791667 | AM20: 0.70555556 | AN20: 0.71597222 | AO20: 0.71944444 | AQ20: 0.75763889 | AR20: 0.76875 | AT20: 0.78333333 | AU20: 0.81180556 | AV20: 0.82013889 | AW20: 0.83958333
A21: HEIDEVELD | B21: -33.96955914627068, 18.561952615501543 | C21: 0.20694444 | D21: 0.2125 | E21: 0.22777778 | F21: 0.23819444 | H21: 0.26458333 | I21: 0.27013889 | K21: 0.28125 | M21: 0.31319444 | N21: 0.31666667 | O21: 0.33541667 | P21: 0.35972222 | Q21: 0.36527778 | S21: 0.38541667 | U21: 0.40972222 | V21: 0.41388889 | X21: 0.45486111 | Y21: 0.46944444 | AA21: 0.5125 | AC21: 0.55763889 | AE21: 0.57152778 | AF21: 0.57361111 | AH21: 0.65138889 | AI21: 0.66736111 | AK21: 0.64930556 | AM21: 0.70694444 | AN21: 0.71736111 | AO21: 0.72083333 | AQ21: 0.75902778 | AR21: 0.77013889 | AT21: 0.78472222 | AU21: 0.81319444 | AV21: 0.82152778
A22: NETREG | B22: -33.952620288476226, 18.563580552945645 | C22: 0.20833333 | D22: 0.21388889 | E22: 0.22916667 | F22: 0.23958333 | H22: 0.26597222 | I22: 0.27152778 | K22: 0.28263889 | M22: 0.31458333 | N22: 0.31805556 | O22: 0.33680556 | P22: 0.36111111 | Q22: 0.36666667 | S22: 0.38680556 | U22: 0.41111111 | V22: 0.41527778 | X22: 0.45625 | Y22: 0.47083333 | AA22: 0.51388889 | AC22: 0.55902778 | AE22: 0.57291667 | AF22: 0.575 | AH22: 0.65277778 | AI22: 0.66875 | AK22: 0.65069444 | AM22: 0.70833333 | AN22: 0.71875 | AO22: 0.72222222 | AQ22: 0.76041667 | AR22: 0.77152778 | AT22: 0.78611111 | AU22: 0.81458333 | AV22: 0.82291667
A23: BONTEHEUWEL | B23: -33.94185049480737, 18.549579817876847 | C23: 0.20972222 | D23: 0.21527778 | E23: 0.23055556 | F23: 0.24097222 | G23: 0.24791667 | H23: 0.26736111 | I23: 0.27291667 | J23: 0.27569444 | K23: 0.28402778 | L23: 0.31041667 | M23: 0.31597222 | N23: 0.31944444 | O23: 0.33819444 | P23: 0.3625 | Q23: 0.36805556 | R23: 0.37291667 | S23: 0.38819444 | T23: 0.39722222 | U23: 0.4125 | V23: 0.41666667 | W23: 0.44930556 | X23: 0.45763889 | Y23: 0.47222222 | Z23: 0.50833333 | AA23: 0.51527778 | AB23: 0.55 | AC23: 0.56041667 | AD23: 0.56736111 | AE23: 0.57430556 | AF23: 0.57638889 | AG23: 0.62986111 | AH23: 0.65416667 | AI23: 0.67013889 | AJ23: 0.66805556 | AK23: 0.65208333 | AL23: 0.69930556 | AM23: 0.70972222 | AN23: 0.72013889 | AO23: 0.72361111 | AP23: 0.75138889 | AQ23: 0.76180556 | AR23: 0.77291667 | AS23: 0.77916667 | AT23: 0.7875 | AU23: 0.81597222 | AV23: 0.82430556 | AW23: 0.84375
A24: LANGA | B24: -33.938934072196076, 18.52974423065194 | C24: 0.21180556 | D24: 0.21736111 | E24: 0.23263889 | F24: 0.24305556 | G24: 0.25 | H24: 0.26944444 | I24: 0.275 | J24: 0.27777778 | K24: 0.28611111 | L24: 0.3125 | M24: 0.31805556 | N24: 0.32152778 | O24: 0.34027778 | P24: 0.36458333 | Q24: 0.37013889 | R24: 0.375 | S24: 0.39027778 | T24: 0.39930556 | U24: 0.41458333 | V24: 0.41875 | W24: 0.45138889 | X24: 0.45972222 | Y24: 0.47430556 | Z24: 0.51041667 | AA24: 0.51736111 | AB24: 0.55208333 | AC24: 0.5625 | AD24: 0.56944444 | AE24: 0.57638889 | AF24: 0.57847222 | AG24: 0.63194444 | AH24: 0.65625 | AI24: 0.67222222 | AJ24: 0.67013889 | AK24: 0.65416667 | AL24: 0.70138889 | AM24: 0.71180556 | AN24: 0.72222222 | AO24: 0.72569444 | AP24: 0.75347222 | AQ24: 0.76388889 | AR24: 0.775 | AS24: 0.78125 | AT24: 0.78958333 | AU24: 0.81805556 | AV24: 0.82638889 | AW24: 0.84583333
A25: MUTUAL | B25: -33.92209345116931, 18.511988082500565 | C25: 0.21527778 | E25: 0.23611111 | F25: 0.24652778 | G25: 0.25347222 | I25: 0.27847222 | J25: 0.28125 | K25: 0.28958333 | L25: 0.31597222 | M25: 0.32152778 | O25: 0.34375 | P25: 0.36805556 | R25: 0.37847222 | S25: 0.39375 | T25: 0.40277778 | U25: 0.41805556 | W25: 0.45486111 | X25: 0.46319444 | Z25: 0.51388889 | AA25: 0.52083333 | AB25: 0.55555556 | AC25: 0.56597222 | AD25: 0.57291667 | AE25: 0.57986111 | AG25: 0.63541667 | AH25: 0.65972222 | AJ25: 0.67361111 | AK25: 0.65763889 | AL25: 0.70486111 | AM25: 0.71527778 | AO25: 0.72916667 | AP25: 0.75694444 | AQ25: 0.76736111 | AS25: 0.78472222 | AT25: 0.79305556 | AV25: 0.82986111
A26: YSTERPLAAT | B26: -33.9199022523178, 18.476775305514295 | C26: 0.22152778 | E26: 0.24236111 | F26: 0.25277778 | I26: 0.28472222 | K26: 0.29583333 | M26: 0.32777778 | O26: 0.35 | P26: 0.37430556 | S26: 0.4 | U26: 0.42430556 | X26: 0.46944444 | AA26: 0.52708333 | AC26: 0.57222222 | AE26: 0.58611111 | AH26: 0.66597222 | AK26: 0.66388889 | AM26: 0.72152778 | AO26: 0.73541667 | AQ26: 0.77361111 | AT26: 0.79930556 | AV26: 0.83611111
A27: ESPLANADE | B27: -33.923640784366874, 18.446037955514498 | C27: 0.22986111 | E27: 0.25069444 | F27: 0.26111111 | I27: 0.29305556 | K27: 0.30416667 | M27: 0.33611111 | O27: 0.35833333 | P27: 0.38263889 | S27: 0.40833333 | U27: 0.43263889 | X27: 0.47777778 | AA27: 0.53541667 | AC27: 0.58055556 | AE27: 0.59444444 | AH27: 0.67430556 | AK27: 0.67222222 | AM27: 0.72986111 | AO27: 0.74375 | AQ27: 0.78194444 | AT27: 0.80763889 | AV27: 0.84444444
A28: PINELANDS | B28: -33.93964476336891, 18.490635019900687 | D28: 0.21944444 | H28: 0.27152778 | N28: 0.32361111 | Q28: 0.37222222 | V28: 0.42083333 | Y28: 0.47638889 | AF28: 0.58055556 | AI28: 0.67430556 | AN28: 0.72430556 | AR28: 0.77708333 | AU28: 0.82013889 | AW28: 0.84791667
A29: NDABENI | B29: -33.928548273196824, 18.495159894144553 | D29: 0.22083333 | H29: 0.27291667 | N29: 0.325 | Q29: 0.37361111 | V29: 0.42222222 | Y29: 0.47777778 | AF29: 0.58194444 | AI29: 0.67569444 | AN29: 0.72569444 | AR29: 0.77847222 | AU29: 0.82152778 | AW29: 0.84930556
A30: MAITLAND | B30: -33.92465193392986, 18.487001988940953 | D30: 0.22291667 | H30: 0.275 | N30: 0.32708333 | Q30: 0.37569444 | V30: 0.42430556 | Y30: 0.47986111 | AF30: 0.58402778 | AI30: 0.67777778 | AN30: 0.72777778 | AR30: 0.78055556 | AU30: 0.82361111 | AW30: 0.85138889
A31: KOEBERG RD | B31: -33.92570961024241, 18.47887742815667 | D31: 0.225 | H31: 0.27708333 | N31: 0.32916667 | Q31: 0.37777778 | V31: 0.42638889 | Y31: 0.48194444 | AF31: 0.58611111 | AI31: 0.67986111 | AN31: 0.72986111 | AR31: 0.78263889 | AU31: 0.82569444 | AW31: 0.85347222
A32: SALT RIVER | B32: -33.92754558428959, 18.464689555116372 | D32: 0.22708333 | H32: 0.27916667 | N32: 0.33125 | Q32: 0.37986111 | V32: 0.42847222 | Y32: 0.48402778 | AF32: 0.58819444 | AI32: 0.68194444 | AN32: 0.73194444 | AR32: 0.78472222 | AU32: 0.82777778 | AW32: 0.85555556
A33: WOODSTOCK | B33: -33.925058308184404, 18.44613913370814 | D33: 0.23055556 | H33: 0.28263889 | N33: 0.33472222 | Q33: 0.38333333 | V33: 0.43194444 | Y33: 0.4875 | AF33: 0.59166667 | AI33: 0.68541667 | AN33: 0.73541667 | AR33: 0.78819444 | AU33: 0.83125 | AW33: 0.85902778
A34: CAPE TOWN | B34: -33.92363127060243, 18.42718648501388 | C34: 0.23611111 | D34: 0.23472222 | E34: 0.25694444 | F34: 0.26736111 | H34: 0.28680556 | I34: 0.29930556 | K34: 0.31041667 | M34: 0.34236111 | N34: 0.33888889 | O34: 0.36111111 | P34: 0.38888889 | Q34: 0.3875 | S34: 0.41805556 | U34: 0.43888889 | V34: 0.43611111 | X34: 0.48472222 | Y34: 0.49166667 | AA34: 0.54166667 | AC34: 0.58680556 | AE34: 0.60069444 | AF34: 0.59583333 | AH34: 0.68055556 | AI34: 0.68958333 | AK34: 0.67847222 | AM34: 0.73611111 | AN34: 0.73958333 | AO34: 0.75 | AQ34: 0.78819444 | AR34: 0.79236111 | AT34: 0.81388889 | AU34: 0.83541667 | AV34: 0.85069444 | AW34: 0.86319444

Sheet CEN_OUT_WK_MASTER
A1: Last Updated: | B1: Unspecified | C1: Z1 | D1: =SORT(A2:A14, ROW(A2:A14), 0)
A2: STATION | B2: COORDINATES | C2: 9703 | D2: 9501 | E2: 9901 | F2: 9001 | G2: 9301 | H2: 9401 | I2: 9503 | J2: 9003 | K2: 9903 | L2: 9005 | M2: 9505 | N2: 9403 | O2: 9905 | P2: 9007 | Q2: 9507 | R2: 9405 | S2: 9009 | T2: 9907 | U2: 9509 | V2: 9011 | W2: 9909 | X2: 9013 | Y2: 9911 | Z2: 9407 | AA2: 9015 | AB2: 9511 | AC2: 9913 | AD2: 9017 | AE2: 9513 | AF2: 9409 | AG2: 9915 | AH2: 9019 | AI2: 9515 | AJ2: 9411 | AK2: 9917 | AL2: 9021 | AM2: 9517 | AN2: 9023 | AO2: 9413 | AP2: 9919 | AQ2: 9519 | AR2: 9025 | AS2: 9415 | AT2: 9027 | AU2: 9521 | AV2: 9921
A3: CAPE TOWN | B3: -33.92363127060243, 18.42718648501388 | C3: 0.14930556 | D3: 0.19444444 | E3: 0.2 | G3: 0.21666667 | H3: 0.24305556 | I3: 0.24652778 | K3: 0.25347222 | M3: 0.3 | N3: 0.29513889 | O3: 0.30555556 | Q3: 0.34722222 | R3: 0.34930556 | T3: 0.375 | U3: 0.39236111 | W3: 0.43055556 | Y3: 0.48611111 | Z3: 0.49652778 | AB3: 0.50694444 | AC3: 0.55902778 | AE3: 0.60277778 | AF3: 0.59027778 | AG3: 0.625 | AI3: 0.64583333 | AJ3: 0.64930556 | AK3: 0.67708333 | AM3: 0.70138889 | AO3: 0.72430556 | AP3: 0.73263889 | AQ3: 0.74652778 | AS3: 0.75694444 | AU3: 0.80069444 | AV3: 0.80208333
A4: WOODSTOCK | B4: -33.925058308184404, 18.44613913370814 | D4: 0.19652778 | G4: 0.21875 | I4: 0.24861111 | M4: 0.30208333 | Q4: 0.34930556 | U4: 0.39444444 | AB4: 0.50902778 | AE4: 0.60486111 | AI4: 0.64791667 | AM4: 0.70347222 | AQ4: 0.74861111 | AU4: 0.80277778
A5: SALT RIVER | B5: -33.92754558428959, 18.464689555116372 | D5: 0.19861111 | G5: 0.22083333 | I5: 0.25069444 | M5: 0.30416667 | Q5: 0.35138889 | U5: 0.39652778 | AB5: 0.51111111 | AE5: 0.60694444 | AI5: 0.65 | AM5: 0.70555556 | AQ5: 0.75069444 | AU5: 0.80486111
A6: KOEBERG RD | B6: -33.92570961024241, 18.47887742815667 | D6: 0.2 | G6: 0.22222222 | I6: 0.25208333 | M6: 0.30555556 | Q6: 0.35277778 | U6: 0.39791667 | AB6: 0.5125 | AE6: 0.60833333 | AI6: 0.65138889 | AM6: 0.70694444 | AQ6: 0.75208333 | AU6: 0.80625
A7: MAITLAND | B7: -33.92465193392986, 18.487001988940953 | D7: 0.20138889 | G7: 0.22361111 | I7: 0.25347222 | M7: 0.30694444 | Q7: 0.35416667 | U7: 0.39930556 | AB7: 0.51388889 | AE7: 0.60972222 | AI7: 0.65277778 | AM7: 0.70833333 | AQ7: 0.75347222 | AU7: 0.80763889
A8: NDABENI | B8: -33.928548273196824, 18.495159894144553 | D8: 0.20347222 | G8: 0.22569444 | I8: 0.25555556 | M8: 0.30902778 | Q8: 0.35625 | U8: 0.40138889 | AB8: 0.51597222 | AE8: 0.61180556 | AI8: 0.65486111 | AM8: 0.71041667 | AQ8: 0.75555556 | AU8: 0.80972222
A9: PINELANDS | B9: -33.93964476336891, 18.490635019900687 | D9: 0.20555556 | G9: 0.22777778 | I9: 0.25763889 | M9: 0.31111111 | Q9: 0.35833333 | U9: 0.40347222 | AB9: 0.51805556 | AE9: 0.61388889 | AI9: 0.65694444 | AM9: 0.7125 | AQ9: 0.75763889 | AU9: 0.81180556
A10: ESPLANADE | B10: -33.923640784366874, 18.446037955514498 | C10: 0.15625 | E10: 0.20694444 | H10: 0.25 | K10: 0.26041667 | N10: 0.30208333 | O10: 0.3125 | R10: 0.35625 | T10: 0.38194444 | W10: 0.4375 | Y10: 0.49305556 | Z10: 0.50347222 | AC10: 0.56597222 | AF10: 0.59722222 | AG10: 0.63194444 | AJ10: 0.65625 | AK10: 0.68402778 | AO10: 0.73125 | AP10: 0.73958333 | AS10: 0.76388889 | AV10: 0.80902778
A11: YSTERPLAAT | B11: -33.9199022523178, 18.476775305514295 | C11: 0.16458333 | E11: 0.21527778 | H11: 0.25833333 | K11: 0.26875 | N11: 0.31041667 | O11: 0.32083333 | R11: 0.36458333 | T11: 0.39027778 | W11: 0.44583333 | Y11: 0.50138889 | Z11: 0.51180556 | AC11: 0.57430556 | AF11: 0.60555556 | AG11: 0.64027778 | AJ11: 0.66458333 | AK11: 0.69236111 | AO11: 0.73958333 | AP11: 0.74791667 | AS11: 0.77222222 | AV11: 0.81736111
A12: MUTUAL | B12: -33.92209345116931, 18.511988082500565 | C12: 0.16805556 | E12: 0.21875 | F12: 0.23263889 | H12: 0.26180556 | J12: 0.26736111 | K12: 0.27222222 | L12: 0.28819444 | N12: 0.31388889 | O12: 0.32430556 | P12: 0.32986111 | R12: 0.36805556 | S12: 0.38541667 | T12: 0.39375 | V12: 0.40625 | W12: 0.44930556 | X12: 0.46180556 | Y12: 0.50486111 | Z12: 0.51527778 | AA12: 0.52083333 | AC12: 0.57777778 | AD12: 0.58333333 | AF12: 0.60902778 | AG12: 0.64375 | AH12: 0.65277778 | AJ12: 0.66805556 | AK12: 0.69583333 | AL12: 0.70138889 | AN12: 0.72222222 | AO12: 0.74305556 | AP12: 0.75138889 | AR12: 0.76388889 | AS12: 0.77569444 | AT12: 0.79166667 | AV12: 0.82083333
A13: LANGA | B13: -33.938934072196076, 18.52974423065194 | C13: 0.17152778 | D13: 0.20972222 | E13: 0.22222222 | F13: 0.23611111 | G13: 0.23194444 | H13: 0.26527778 | I13: 0.26180556 | J13: 0.27083333 | K13: 0.27569444 | L13: 0.29166667 | M13: 0.31527778 | N13: 0.31736111 | O13: 0.32777778 | P13: 0.33333333 | Q13: 0.3625 | R13: 0.37152778 | S13: 0.38888889 | T13: 0.39722222 | U13: 0.40763889 | V13: 0.40972222 | W13: 0.45277778 | X13: 0.46527778 | Y13: 0.50833333 | Z13: 0.51875 | AA13: 0.52430556 | AB13: 0.52222222 | AC13: 0.58125 | AD13: 0.58680556 | AE13: 0.61805556 | AF13: 0.6125 | AG13: 0.64722222 | AH13: 0.65625 | AI13: 0.66111111 | AJ13: 0.67152778 | AK13: 0.69930556 | AL13: 0.70486111 | AM13: 0.71666667 | AN13: 0.72569444 | AO13: 0.74652778 | AP13: 0.75486111 | AQ13: 0.76180556 | AR13: 0.76736111 | AS13: 0.77916667 | AT13: 0.79513889 | AU13: 0.81597222 | AV13: 0.82430556
A14: BONTEHEUWEL | B14: -33.94185049480737, 18.549579817876847 | C14: 0.17291667 | D14: 0.21111111 | E14: 0.22361111 | F14: 0.2375 | G14: 0.23333333 | H14: 0.26666667 | I14: 0.26319444 | J14: 0.27222222 | K14: 0.27708333 | L14: 0.29305556 | M14: 0.31666667 | N14: 0.31875 | O14: 0.32916667 | P14: 0.33472222 | Q14: 0.36388889 | R14: 0.37291667 | S14: 0.39027778 | T14: 0.39861111 | U14: 0.40902778 | V14: 0.41111111 | W14: 0.45416667 | X14: 0.46666667 | Y14: 0.50972222 | Z14: 0.52013889 | AA14: 0.52569444 | AB14: 0.52361111 | AC14: 0.58263889 | AD14: 0.58819444 | AE14: 0.61944444 | AF14: 0.61388889 | AG14: 0.64861111 | AH14: 0.65763889 | AI14: 0.6625 | AJ14: 0.67291667 | AK14: 0.70069444 | AL14: 0.70625 | AM14: 0.71805556 | AN14: 0.72708333 | AO14: 0.74791667 | AP14: 0.75625 | AQ14: 0.76319444 | AR14: 0.76875 | AS14: 0.78055556 | AT14: 0.79652778 | AU14: 0.81736111 | AV14: 0.82569444
A15: NETREG | B15: -33.952666168847884, 18.56356622880313 | C15: 0.17430556 | D15: 0.2125 | E15: 0.225 | G15: 0.23472222 | H15: 0.26805556 | I15: 0.26458333 | K15: 0.27847222 | M15: 0.31805556 | N15: 0.32013889 | O15: 0.33055556 | Q15: 0.36527778 | R15: 0.37430556 | T15: 0.4 | U15: 0.41041667 | W15: 0.45555556 | Y15: 0.51111111 | Z15: 0.52152778 | AB15: 0.525 | AC15: 0.58402778 | AE15: 0.62083333 | AF15: 0.61527778 | AG15: 0.65 | AI15: 0.66388889 | AJ15: 0.67430556 | AK15: 0.70208333 | AM15: 0.71944444 | AO15: 0.74930556 | AP15: 0.75763889 | AQ15: 0.76458333 | AS15: 0.78194444 | AU15: 0.81875 | AV15: 0.82708333
A16: HEIDEVELD | B16: -33.969594701133275, 18.56187725551686 | C16: 0.175 | D16: 0.21319444 | E16: 0.22569444 | G16: 0.23541667 | H16: 0.26875 | I16: 0.26527778 | K16: 0.27916667 | M16: 0.31875 | N16: 0.32083333 | O16: 0.33125 | Q16: 0.36597222 | R16: 0.375 | T16: 0.40069444 | U16: 0.41111111 | W16: 0.45625 | Y16: 0.51180556 | Z16: 0.52222222 | AB16: 0.52569444 | AC16: 0.58472222 | AE16: 0.62152778 | AF16: 0.61597222 | AG16: 0.65069444 | AI16: 0.66458333 | AJ16: 0.675 | AK16: 0.70277778 | AM16: 0.72013889 | AO16: 0.75 | AP16: 0.75833333 | AQ16: 0.76527778 | AS16: 0.78263889 | AU16: 0.81944444 | AV16: 0.82777778
A17: NYANGA | B17: -33.99271379632963, 18.559776951819032 | C17: 0.17777778 | D17: 0.21597222 | E17: 0.22847222 | G17: 0.23819444 | H17: 0.27152778 | I17: 0.26805556 | K17: 0.28194444 | M17: 0.32152778 | N17: 0.32361111 | O17: 0.33402778 | Q17: 0.36875 | R17: 0.37777778 | T17: 0.40347222 | U17: 0.41388889 | W17: 0.45902778 | Y17: 0.51458333 | Z17: 0.525 | AB17: 0.52847222 | AC17: 0.5875 | AE17: 0.62430556 | AF17: 0.61875 | AG17: 0.65347222 | AI17: 0.66736111 | AJ17: 0.67777778 | AK17: 0.70555556 | AM17: 0.72291667 | AO17: 0.75277778 | AP17: 0.76111111 | AQ17: 0.76805556 | AS17: 0.78541667 | AU17: 0.82222222 | AV17: 0.83055556
A18: PHILIPPI | B18: -34.01328895709482, 18.584421561340882 | C18: 0.18194444 | D18: 0.22013889 | E18: 0.23263889 | G18: 0.24236111 | H18: 0.27569444 | I18: 0.27222222 | K18: 0.28611111 | M18: 0.32569444 | N18: 0.32777778 | O18: 0.33819444 | Q18: 0.37291667 | R18: 0.38194444 | T18: 0.40763889 | U18: 0.41805556 | W18: 0.46319444 | Y18: 0.51875 | Z18: 0.52916667 | AB18: 0.53263889 | AC18: 0.59166667 | AE18: 0.62847222 | AF18: 0.62083333 | AG18: 0.65763889 | AI18: 0.67152778 | AJ18: 0.68194444 | AK18: 0.70972222 | AM18: 0.72708333 | AO18: 0.75694444 | AP18: 0.76527778 | AQ18: 0.77222222 | AS18: 0.78958333 | AU18: 0.82638889 | AV18: 0.83263889
A19: LENTEGEUR | B19: -34.03418971685345, 18.611322738328173 | D19: 0.22569444 | I19: 0.27777778 | M19: 0.33125 | Q19: 0.37847222 | U19: 0.42361111 | AB19: 0.53819444 | AE19: 0.63402778 | AI19: 0.67708333 | AM19: 0.73263889 | AQ19: 0.77777778 | AU19: 0.83194444
A20: MITCHELL'S PLAIN | B20: -34.0504610838304, 18.619222253671435 | D20: 0.23055556 | I20: 0.28263889 | M20: 0.33611111 | Q20: 0.38333333 | U20: 0.42847222 | AB20: 0.54305556 | AE20: 0.63888889 | AI20: 0.68194444 | AM20: 0.7375 | AQ20: 0.78263889 | AU20: 0.83680556
A21: KAPTEINSKLIP | B21: -34.06755873543257, 18.620534480658506 | D21: 0.23402778 | I21: 0.28611111 | M21: 0.33958333 | Q21: 0.38680556 | U21: 0.43194444 | AB21: 0.54652778 | AE21: 0.64236111 | AI21: 0.68541667 | AM21: 0.74097222 | AQ21: 0.78611111 | AU21: 0.84027778
A22: STOCK ROAD | B22: -34.01412292128464, 18.606174209491407 | C22: 0.18472222 | E22: 0.23541667 | G22: 0.24513889 | H22: 0.27847222 | K22: 0.28888889 | N22: 0.33055556 | O22: 0.34097222 | R22: 0.38472222 | T22: 0.41041667 | W22: 0.46597222 | Y22: 0.52152778 | Z22: 0.53194444 | AC22: 0.59444444 | AF22: 0.62361111 | AG22: 0.66041667 | AJ22: 0.68472222 | AK22: 0.7125 | AO22: 0.75972222 | AP22: 0.76805556 | AS22: 0.79236111 | AV22: 0.83541667
A23: MANDALAY | B23: -34.019015667481014, 18.624391145998562 | C23: 0.1875 | E23: 0.23819444 | G23: 0.24791667 | H23: 0.28125 | K23: 0.29166667 | N23: 0.33333333 | O23: 0.34375 | R23: 0.3875 | T23: 0.41319444 | W23: 0.46875 | Y23: 0.52430556 | Z23: 0.53472222 | AC23: 0.59722222 | AF23: 0.62638889 | AG23: 0.66319444 | AJ23: 0.6875 | AK23: 0.71527778 | AO23: 0.7625 | AP23: 0.77083333 | AS23: 0.79513889 | AV23: 0.83819444
A24: NOLUNGILE | B24: -34.016811809063164, 18.64902361716287 | C24: 0.18819444 | E24: 0.24097222 | G24: 0.25069444 | H24: 0.28402778 | K24: 0.29444444 | N24: 0.33611111 | O24: 0.34652778 | R24: 0.39027778 | T24: 0.41597222 | W24: 0.47152778 | Y24: 0.52708333 | Z24: 0.5375 | AC24: 0.6 | AF24: 0.63194444 | AG24: 0.66597222 | AJ24: 0.69027778 | AK24: 0.71805556 | AO24: 0.76527778 | AP24: 0.77361111 | AS24: 0.79861111 | AV24: 0.84097222
A25: NONKQUBELA | B25: -34.02681746271161, 18.663190611341626 | E25: 0.24375 | K25: 0.29722222 | O25: 0.34930556 | T25: 0.41875 | W25: 0.47430556 | Y25: 0.52986111 | AC25: 0.60277778 | AG25: 0.66875 | AK25: 0.72083333 | AP25: 0.77638889 | AV25: 0.84375
A26: KHAYELITSHA | B26: -34.047943373751565, 18.67073769040669 | E26: 0.24652778 | K26: 0.3 | O26: 0.35208333 | T26: 0.42152778 | W26: 0.47708333 | Y26: 0.53263889 | AC26: 0.60555556 | AG26: 0.67152778 | AK26: 0.72361111 | AP26: 0.77916667 | AV26: 0.84652778
A27: KUYASA | B27: -34.05489939537871, 18.692323957717754 | E27: 0.24861111 | K27: 0.30208333 | O27: 0.35416667 | T27: 0.42361111 | W27: 0.47916667 | Y27: 0.53472222 | AC27: 0.60763889 | AG27: 0.67361111 | AK27: 0.72569444 | AP27: 0.78125 | AV27: 0.84861111
A28: CHRIS HANI | B28: -34.054706073305944, 18.710707924836054 | E28: 0.25138889 | K28: 0.30486111 | O28: 0.35486111 | T28: 0.42638889 | W28: 0.47986111 | Y28: 0.5375 | AC28: 0.61041667 | AG28: 0.67430556 | AK28: 0.72847222 | AP28: 0.78402778 | AV28: 0.85138889
A29: LAVISTOWN | B29: -33.943269567798055, 18.583722311337315 | F29: 0.23958333 | J29: 0.27430556 | L29: 0.29513889 | P29: 0.33680556 | S29: 0.39236111 | V29: 0.41319444 | X29: 0.46875 | AA29: 0.52777778 | AD29: 0.59027778 | AH29: 0.65972222 | AL29: 0.70833333 | AN29: 0.72916667 | AR29: 0.77083333 | AT29: 0.79861111
A30: BELHAR | B30: -33.93959717971092, 18.60894476900841 | F30: 0.24305556 | J30: 0.27777778 | L30: 0.29861111 | P30: 0.34027778 | S30: 0.39583333 | V30: 0.41666667 | X30: 0.47222222 | AA30: 0.53125 | AD30: 0.59375 | AH30: 0.66319444 | AL30: 0.71180556 | AN30: 0.73263889 | AR30: 0.77430556 | AT30: 0.80208333
A31: UNIBELL | B31: -33.93686354314193, 18.628117540172582 | F31: 0.24513889 | J31: 0.27986111 | L31: 0.30069444 | P31: 0.34236111 | S31: 0.39791667 | V31: 0.41875 | X31: 0.47430556 | AA31: 0.53333333 | AD31: 0.59583333 | AH31: 0.66527778 | AL31: 0.71388889 | AN31: 0.73472222 | AR31: 0.77638889 | AT31: 0.80416667
A32: PENTECH | B32: -33.93468015167005, 18.646053668734744 | F32: 0.24791667 | J32: 0.28263889 | L32: 0.30347222 | P32: 0.34513889 | S32: 0.40069444 | V32: 0.42152778 | X32: 0.47708333 | AA32: 0.53611111 | AD32: 0.59861111 | AH32: 0.66805556 | AL32: 0.71666667 | AN32: 0.7375 | AR32: 0.77916667 | AT32: 0.80694444
A33: SAREPTA | B33: -33.92655594121331, 18.661143180651308 | F33: 0.25 | J33: 0.28472222 | L33: 0.30555556 | P33: 0.34722222 | S33: 0.40277778 | V33: 0.42361111 | X33: 0.47916667 | AA33: 0.53819444 | AD33: 0.60069444 | AH33: 0.67013889 | AL33: 0.71875 | AN33: 0.73958333 | AR33: 0.78125 | AT33: 0.80902778
A34: BELLVILLE | B34: -33.906263459762684, 18.62662128465745 | F34: 0.25347222 | J34: 0.28819444 | L34: 0.30902778 | P34: 0.35069444 | S34: 0.40625 | V34: 0.42708333 | X34: 0.48263889 | AA34: 0.54166667 | AD34: 0.60416667 | AH34: 0.67361111 | AL34: 0.72222222 | AN34: 0.74305556 | AR34: 0.78472222 | AT34: 0.8125

Sheet CEN_IN_SAT_MASTER
A1: Last Updated: | B1: Unspecified | C1: Z1
A2: STATION | B2: COORDINATES | C2: 9400 | D2: 9500 | E2: 9900 | F2: 9002 | G2: 9402 | H2: 9502 | I2: 9902 | J2: 9004 | K2: 9404 | L2: 9504 | M2: 9904 | N2: 9008 | O2: 9406 | P2: 9506 | Q2: 9906 | R2: 9508 | S2: 9008 | T2: 9908 | U2: 9510 | V2: 9010 | W2: 9910 | X2: 9512 | Y2: 9408 | Z2: 9514 | AA2: 9012 | AB2: 9912
A3: BELLVILLE | B3: -33.906263459762684, 18.62662128465745 | F3: 0.24305556 | J3: 0.30555556 | N3: 0.36111111 | S3: 0.45138889 | V3: 0.50694444 | AA3: 0.5625
A4: SAREPTA | B4: -33.92655594121331, 18.661143180651308 | F4: 0.24722222 | J4: 0.30972222 | N4: 0.36527778 | S4: 0.45555556 | V4: 0.51111111 | AA4: 0.56666667
A5: PENTECH | B5: -33.93468015167005, 18.646053668734744 | F5: 0.24930556 | J5: 0.31180556 | N5: 0.36736111 | S5: 0.45763889 | V5: 0.51319444 | AA5: 0.56875
A6: UNIBELL | B6: -33.93686354314193, 18.628117540172582 | F6: 0.25208333 | J6: 0.31458333 | N6: 0.37013889 | S6: 0.46041667 | V6: 0.51597222 | AA6: 0.57152778
A7: BELHAR | B7: -33.93959717971092, 18.60894476900841 | F7: 0.25486111 | J7: 0.31736111 | N7: 0.37291667 | S7: 0.46319444 | V7: 0.51875 | AA7: 0.57430556
A8: LAVISTOWN | B8: -33.943269567798055, 18.583722311337315 | F8: 0.25694444 | J8: 0.31944444 | N8: 0.375 | S8: 0.46527778 | V8: 0.52083333 | AA8: 0.57638889
A9: CHRIS HANI | B9: -34.054706073305944, 18.710707924836054 | E9: 0.21527778 | I9: 0.28472222 | M9: 0.34166667 | Q9: 0.40277778 | T9: 0.45486111 | W9: 0.50694444 | AB9: 0.60416667
A10: KUYASA | B10: -34.05489939537871, 18.692323957717754 | E10: 0.21805556 | I10: 0.2875 | M10: 0.34444444 | Q10: 0.40555556 | T10: 0.45763889 | W10: 0.50972222 | AB10: 0.60694444
A11: KHAYELITSHA | B11: -34.047943373751565, 18.67073769040669 | E11: 0.22013889 | I11: 0.28958333 | M11: 0.34652778 | Q11: 0.40763889 | T11: 0.45972222 | W11: 0.51180556 | AB11: 0.60902778
A12: NONKQUBELA | B12: -34.02681746271161, 18.663190611341626 | E12: 0.22291667 | I12: 0.29236111 | M12: 0.34930556 | Q12: 0.41041667 | T12: 0.4625 | W12: 0.51458333 | AB12: 0.61180556
A13: NOLUNGILE | B13: -34.016811809063164, 18.64902361716287 | C13: 0.19444444 | E13: 0.22569444 | G13: 0.25833333 | I13: 0.29513889 | K13: 0.31597222 | M13: 0.35208333 | O13: 0.37152778 | Q13: 0.41319444 | T13: 0.46527778 | W13: 0.51736111 | Y13: 0.54513889 | AB13: 0.61458333
A14: MANDALAY | B14: -34.019015667481014, 18.624391145998562 | C14: 0.19722222 | E14: 0.22847222 | G14: 0.26111111 | I14: 0.29791667 | K14: 0.31875 | M14: 0.35486111 | O14: 0.37430556 | Q14: 0.41597222 | T14: 0.46805556 | W14: 0.52013889 | Y14: 0.54791667 | AB14: 0.61736111
A15: STOCK ROAD | B15: -34.01412292128464, 18.606174209491407 | C15: 0.19930556 | E15: 0.23055556 | G15: 0.26319444 | I15: 0.3 | K15: 0.32083333 | M15: 0.35694444 | O15: 0.37638889 | Q15: 0.41805556 | T15: 0.47013889 | W15: 0.52222222 | Y15: 0.55 | AB15: 0.61944444
A16: KAPTEINSKLIP | B16: -34.06755873543257, 18.620534480658506 | D16: 0.19791667 | H16: 0.27569444 | L16: 0.32291667 | P16: 0.375 | R16: 0.42847222 | U16: 0.48611111 | X16: 0.52777778 | Z16: 0.58680556
A17: MITCHELL'S PLAIN | B17: -34.0504610838304, 18.619222253671435 | D17: 0.20347222 | H17: 0.28125 | L17: 0.32847222 | P17: 0.38055556 | R17: 0.43402778 | U17: 0.49166667 | X17: 0.53333333 | Z17: 0.59236111
A18: LENTEGEUR | B18: -34.03418971685345, 18.611322738328173 | D18: 0.20833333 | H18: 0.28611111 | L18: 0.33333333 | P18: 0.38541667 | R18: 0.43888889 | U18: 0.49652778 | X18: 0.53819444 | Z18: 0.59722222
A19: PHILIPPI | B19: -34.01328895709482, 18.584421561340882 | C19: 0.20277778 | D19: 0.21180556 | E19: 0.23402778 | G19: 0.26666667 | H19: 0.28958333 | I19: 0.30347222 | K19: 0.32430556 | L19: 0.33680556 | M19: 0.36041667 | O19: 0.37986111 | P19: 0.38888889 | Q19: 0.42152778 | R19: 0.44236111 | T19: 0.47361111 | U19: 0.5 | W19: 0.52569444 | X19: 0.54166667 | Y19: 0.55347222 | Z19: 0.60069444 | AB19: 0.62291667
A20: NYANGA | B20: -33.99271379632963, 18.559776951819032 | C20: 0.20555556 | D20: 0.21458333 | E20: 0.23680556 | G20: 0.26944444 | H20: 0.29236111 | I20: 0.30625 | K20: 0.32708333 | L20: 0.33958333 | M20: 0.36319444 | O20: 0.38263889 | P20: 0.39166667 | Q20: 0.42430556 | R20: 0.44513889 | T20: 0.47638889 | U20: 0.50277778 | W20: 0.52847222 | X20: 0.54444444 | Y20: 0.55625 | Z20: 0.60347222 | AB20: 0.62569444
A21: BONTEHEUWEL | B21: -33.94185049480737, 18.549579817876847 | C21: 0.20972222 | D21: 0.21875 | E21: 0.24027778 | F21: 0.25833333 | G21: 0.27361111 | H21: 0.29652778 | I21: 0.31041667 | J21: 0.32083333 | K21: 0.33125 | L21: 0.34375 | M21: 0.36736111 | N21: 0.37638889 | O21: 0.38680556 | P21: 0.39583333 | Q21: 0.42847222 | R21: 0.44930556 | S21: 0.46666667 | T21: 0.48055556 | U21: 0.50694444 | V21: 0.52222222 | W21: 0.53263889 | X21: 0.54861111 | Y21: 0.56041667 | Z21: 0.60763889 | AA21: 0.57777778 | AB21: 0.62986111
A22: LANGA | B22: -33.938934072196076, 18.52974423065194 | C22: 0.21180556 | D22: 0.22083333 | E22: 0.24236111 | F22: 0.26041667 | G22: 0.27569444 | H22: 0.29861111 | I22: 0.3125 | J22: 0.32291667 | K22: 0.33333333 | L22: 0.34583333 | M22: 0.36944444 | N22: 0.37847222 | O22: 0.38888889 | P22: 0.39791667 | Q22: 0.43055556 | R22: 0.45138889 | S22: 0.46875 | T22: 0.48263889 | U22: 0.50902778 | V22: 0.52430556 | W22: 0.53472222 | X22: 0.55069444 | Y22: 0.5625 | Z22: 0.60972222 | AA22: 0.57986111 | AB22: 0.63194444
A23: MUTUAL | B23: -33.92209345116931, 18.511988082500565 | C23: 0.21527778 | E23: 0.24583333 | F23: 0.26388889 | G23: 0.27916667 | I23: 0.31597222 | J23: 0.32638889 | K23: 0.33680556 | M23: 0.37291667 | N23: 0.38194444 | O23: 0.39236111 | Q23: 0.43402778 | S23: 0.47222222 | T23: 0.48611111 | V23: 0.52777778 | W23: 0.53819444 | Y23: 0.56597222 | AA23: 0.58333333 | AB23: 0.63541667
A24: YSTERPLAAT | B24: -33.9199022523178, 18.476775305514295 | C24: 0.22152778 | E24: 0.25208333 | G24: 0.28541667 | I24: 0.32222222 | K24: 0.34305556 | M24: 0.37916667 | O24: 0.39861111 | Q24: 0.44027778 | T24: 0.49236111 | W24: 0.54444444 | Y24: 0.57222222 | AB24: 0.64166667
A25: ESPLANADE | B25: -33.923640784366874, 18.446037955514498 | C25: 0.22986111 | E25: 0.26041667 | G25: 0.29375 | I25: 0.33055556 | K25: 0.35138889 | M25: 0.3875 | O25: 0.40694444 | Q25: 0.44861111 | T25: 0.50069444 | W25: 0.55277778 | Y25: 0.58055556 | AB25: 0.65
A26: PINELANDS | B26: -33.93964476336891, 18.490635019900687 | D26: 0.22291667 | H26: 0.30069444 | L26: 0.34791667 | P26: 0.4 | R26: 0.45347222 | U26: 0.51111111 | X26: 0.55277778 | Z26: 0.61180556
A27: NDABENI | B27: -33.928548273196824, 18.495159894144553 | D27: 0.22430556 | H27: 0.30208333 | L27: 0.34930556 | P27: 0.40138889 | R27: 0.45486111 | U27: 0.5125 | X27: 0.55416667 | Z27: 0.61319444
A28: MAITLAND | B28: -33.92465193392986, 18.487001988940953 | D28: 0.22638889 | H28: 0.30416667 | L28: 0.35138889 | P28: 0.40347222 | R28: 0.45694444 | U28: 0.51458333 | X28: 0.55625 | Z28: 0.61527778
A29: KOEBERG RD | B29: -33.92570961024241, 18.47887742815667 | D29: 0.22847222 | H29: 0.30625 | L29: 0.35347222 | P29: 0.40555556 | R29: 0.45902778 | U29: 0.51666667 | X29: 0.55833333 | Z29: 0.61736111
A30: SALT RIVER | B30: -33.92754558428959, 18.464689555116372 | D30: 0.23055556 | H30: 0.30833333 | L30: 0.35555556 | P30: 0.40763889 | R30: 0.46111111 | U30: 0.51875 | X30: 0.56041667 | Z30: 0.61944444
A31: WOODSTOCK | B31: -33.925058308184404, 18.44613913370814 | D31: 0.23402778 | H31: 0.31180556 | L31: 0.35902778 | P31: 0.41111111 | R31: 0.46458333 | U31: 0.52222222 | X31: 0.56388889 | Z31: 0.62291667
A32: CAPE TOWN | B32: -33.92363127060243, 18.42718648501388 | C32: 0.23611111 | D32: 0.23819444 | E32: 0.26736111 | G32: 0.3 | H32: 0.31597222 | I32: 0.33680556 | K32: 0.35763889 | L32: 0.36319444 | M32: 0.39375 | O32: 0.41388889 | P32: 0.41527778 | Q32: 0.45486111 | R32: 0.46875 | T32: 0.50694444 | U32: 0.52638889 | W32: 0.55902778 | X32: 0.56805556 | Y32: 0.58680556 | Z32: 0.62708333 | AB32: 0.65625

Sheet CEN_OUT_SAT_MASTER
A1: Last Updated: | B1: Unspecified
A2: STATION | B2: COORDINATES | C2: 9401 | D2: 9501 | E2: 9901 | F2: 9503 | G2: 9001 | H2: 9403 | I2: 9903 | J2: 9003 | K2: 9505 | L2: 9405 | M2: 9905 | N2: 9005 | O2: 9507 | P2: 9907 | Q2: 9509 | R2: 9909 | S2: 9007 | T2: 9511 | U2: 9407 | V2: 9009 | W2: 9513 | X2: 9911
A3: CAPE TOWN | B3: -33.92363127060243, 18.42718648501388 | C3: 0.20972222 | D3: 0.22916667 | E3: 0.22916667 | F3: 0.27430556 | H3: 0.26388889 | I3: 0.28472222 | K3: 0.32291667 | L3: 0.32291667 | M3: 0.34375 | O3: 0.38194444 | P3: 0.39583333 | Q3: 0.43055556 | R3: 0.45138889 | T3: 0.47916667 | U3: 0.5 | W3: 0.53819444 | X3: 0.54861111
A4: WOODSTOCK | B4: -33.925058308184404, 18.44613913370814 | D4: 0.23125 | F4: 0.27638889 | K4: 0.325 | O4: 0.38402778 | Q4: 0.43263889 | T4: 0.48125 | W4: 0.54027778
A5: SALT RIVER | B5: -33.92754558428959, 18.464689555116372 | D5: 0.23333333 | F5: 0.27847222 | K5: 0.32708333 | O5: 0.38611111 | Q5: 0.43472222 | T5: 0.48333333 | W5: 0.54236111
A6: KOEBERG RD | B6: -33.92570961024241, 18.47887742815667 | D6: 0.23472222 | F6: 0.27986111 | K6: 0.32847222 | O6: 0.3875 | Q6: 0.43611111 | T6: 0.48472222 | W6: 0.54375
A7: MAITLAND | B7: -33.92465193392986, 18.487001988940953 | D7: 0.23611111 | F7: 0.28125 | K7: 0.32986111 | O7: 0.38888889 | Q7: 0.4375 | T7: 0.48611111 | W7: 0.54513889
A8: NDABENI | B8: -33.928548273196824, 18.495159894144553 | D8: 0.23819444 | F8: 0.28333333 | K8: 0.33194444 | O8: 0.39097222 | Q8: 0.43958333 | T8: 0.48819444 | W8: 0.54722222
A9: PINELANDS | B9: -33.93964476336891, 18.490635019900687 | D9: 0.24027778 | F9: 0.28541667 | K9: 0.33402778 | O9: 0.39305556 | Q9: 0.44166667 | T9: 0.49027778 | W9: 0.54930556
A10: ESPLANADE | B10: -33.923640784366874, 18.446037955514498 | C10: 0.21666667 | E10: 0.23611111 | H10: 0.27083333 | I10: 0.29166667 | L10: 0.32986111 | M10: 0.35069444 | P10: 0.40277778 | R10: 0.45833333 | U10: 0.50694444 | X10: 0.55555556
A11: YSTERPLAAT | B11: -33.9199022523178, 18.476775305514295 | C11: 0.225 | E11: 0.24444444 | H11: 0.27916667 | I11: 0.3 | L11: 0.33819444 | M11: 0.35902778 | P11: 0.41111111 | R11: 0.46666667 | U11: 0.51527778 | X11: 0.56388889
A12: MUTUAL | B12: -33.92209345116931, 18.511988082500565 | C12: 0.22847222 | E12: 0.24791667 | G12: 0.27083333 | H12: 0.28263889 | I12: 0.30347222 | J12: 0.33333333 | L12: 0.34166667 | M12: 0.3625 | N12: 0.38888889 | P12: 0.41458333 | R12: 0.47013889 | S12: 0.47916667 | U12: 0.51875 | V12: 0.53472222 | X12: 0.56736111
A13: LANGA | B13: -33.938934072196076, 18.52974423065194 | C13: 0.23194444 | D13: 0.24444444 | E13: 0.25138889 | F13: 0.28958333 | G13: 0.27430556 | H13: 0.28611111 | I13: 0.30694444 | J13: 0.33680556 | K13: 0.33819444 | L13: 0.34513889 | M13: 0.36597222 | N13: 0.39236111 | O13: 0.39722222 | P13: 0.41805556 | Q13: 0.44583333 | R13: 0.47361111 | S13: 0.48263889 | T13: 0.49444444 | U13: 0.52222222 | V13: 0.53819444 | W13: 0.55347222 | X13: 0.57083333
A14: BONTEHEUWEL | B14: -33.94185049480737, 18.549579817876847 | C14: 0.23333333 | D14: 0.24583333 | E14: 0.25277778 | F14: 0.29097222 | G14: 0.27569444 | H14: 0.2875 | I14: 0.30833333 | J14: 0.33819444 | K14: 0.33958333 | L14: 0.34652778 | M14: 0.36736111 | N14: 0.39375 | O14: 0.39861111 | P14: 0.41944444 | Q14: 0.44722222 | R14: 0.475 | S14: 0.48402778 | T14: 0.49583333 | U14: 0.52361111 | V14: 0.53958333 | W14: 0.55486111 | X14: 0.57222222
A15: NYANGA | B15: -33.99271379632963, 18.559776951819032 | C15: 0.23819444 | D15: 0.25069444 | E15: 0.25763889 | F15: 0.29583333 | H15: 0.29236111 | I15: 0.31319444 | K15: 0.34444444 | L15: 0.35138889 | M15: 0.37222222 | O15: 0.40347222 | P15: 0.42430556 | Q15: 0.45208333 | R15: 0.47986111 | T15: 0.50069444 | U15: 0.52847222 | W15: 0.55972222 | X15: 0.57708333
A16: PHILIPPI | B16: -34.01328895709482, 18.584421561340882 | C16: 0.24027778 | D16: 0.25486111 | E16: 0.25972222 | F16: 0.3 | H16: 0.29444444 | I16: 0.31527778 | K16: 0.34861111 | L16: 0.35347222 | M16: 0.37430556 | O16: 0.40763889 | P16: 0.42638889 | Q16: 0.45625 | R16: 0.48402778 | T16: 0.50486111 | U16: 0.53055556 | W16: 0.56388889 | X16: 0.57916667
A17: LENTEGEUR | B17: -34.03418971685345, 18.611322738328173 | D17: 0.26041667 | F17: 0.30555556 | K17: 0.35416667 | O17: 0.41319444 | Q17: 0.46180556 | T17: 0.51041667 | W17: 0.56944444
A18: MITCHELL'S PLAIN | B18: -34.0504610838304, 18.619222253671435 | D18: 0.26527778 | F18: 0.31041667 | K18: 0.35902778 | O18: 0.41805556 | Q18: 0.46666667 | T18: 0.51527778 | W18: 0.57430556
A19: KAPTEINSKLIP | B19: -34.06755873543257, 18.620534480658506 | D19: 0.26875 | F19: 0.31388889 | K19: 0.3625 | O19: 0.42152778 | Q19: 0.47013889 | T19: 0.51875 | W19: 0.57777778
A20: STOCK ROAD | B20: -34.01412292128464, 18.606174209491407 | C20: 0.24305556 | E20: 0.2625 | H20: 0.29722222 | I20: 0.31805556 | L20: 0.35625 | M20: 0.37708333 | P20: 0.42916667 | R20: 0.48680556 | U20: 0.53333333 | X20: 0.58194444
A21: MANDALAY | B21: -34.019015667481014, 18.624391145998562 | C21: 0.24583333 | E21: 0.26527778 | H21: 0.3 | I21: 0.32083333 | L21: 0.35902778 | M21: 0.37986111 | P21: 0.43194444 | R21: 0.48958333 | U21: 0.53611111 | X21: 0.58472222
A22: NOLUNGILE | B22: -34.016811809063164, 18.64902361716287 | C22: 0.24861111 | E22: 0.26805556 | H22: 0.30277778 | I22: 0.32361111 | L22: 0.36180556 | M22: 0.38263889 | P22: 0.43472222 | R22: 0.49236111 | U22: 0.53888889 | X22: 0.5875
A23: NONKQUBELA | B23: -34.02681746271161, 18.663190611341626 | E23: 0.27083333 | I23: 0.32638889 | M23: 0.38541667 | P23: 0.4375 | R23: 0.49513889 | X23: 0.59027778
A24: KHAYELITSHA | B24: -34.047943373751565, 18.67073769040669 | E24: 0.27361111 | I24: 0.32916667 | M24: 0.38819444 | P24: 0.44027778 | R24: 0.49791667 | X24: 0.59305556
A25: KUYASA | B25: -34.05489939537871, 18.692323957717754 | E25: 0.27569444 | I25: 0.33125 | M25: 0.39027778 | P25: 0.44236111 | R25: 0.5 | X25: 0.59513889
A26: CHRIS HANI | B26: -34.054706073305944, 18.710707924836054 | E26: 0.27847222 | I26: 0.33402778 | M26: 0.39305556 | P26: 0.44513889 | R26: 0.50069444 | X26: 0.59791667
A27: LAVISTOWN | B27: -33.943269567798055, 18.583722311337315 | G27: 0.27777778 | J27: 0.34027778 | N27: 0.39583333 | S27: 0.48611111 | V27: 0.54166667
A28: BELHAR | B28: -33.93959717971092, 18.60894476900841 | G28: 0.28125 | J28: 0.34375 | N28: 0.39930556 | S28: 0.48958333 | V28: 0.54513889
A29: UNIBELL | B29: -33.93686354314193, 18.628117540172582 | G29: 0.28333333 | J29: 0.34583333 | N29: 0.40138889 | S29: 0.49166667 | V29: 0.54722222
A30: PENTECH | B30: -33.93468015167005, 18.646053668734744 | G30: 0.28611111 | J30: 0.34861111 | N30: 0.40416667 | S30: 0.49444444 | V30: 0.55
A31: SAREPTA | B31: -33.92655594121331, 18.661143180651308 | G31: 0.28819444 | J31: 0.35069444 | N31: 0.40625 | S31: 0.49652778 | V31: 0.55208333
A32: BELLVILLE | B32: -33.906263459762684, 18.62662128465745 | G32: 0.29166667 | J32: 0.35416667 | N32: 0.40972222 | S32: 0.5 | V32: 0.55555556

Sheet Config_GridOrder
A1: Key,SheetName,RowNumber,StartCol
A2: ctcen_in_weekday,CTCEN-IN_Weekday,2,C
A3: ctcen_out_weekday,CTCEN-OUT_Weekday,2,C
A4: ctcen_in_sat,CTCEN-IN_Sat,2,C
A5: ctcen_out_sat,CTCEN-OUT_Sat,2,C
A6: ct_to_hani_weekday,CT-to-HANI_Weekday,2,C
A7: hani_to_ct_weekday,HANI-to-CT_Weekday,2,C
A8: ct_to_hani_sat,CT-to-HANI_Sat,2,C
A9: hani_to_ct_sat,HANI-to-CT_Sat,2,C
A10: ct_to_kap_weekday,CT-to-KAP_Weekday,2,C
A11: kap_to_ct_weekday,KAP-to-CT_Weekday,2,C
A12: ct_to_kap_sat,CT-to-KAP_Sat,2,C
... A61: event_to_b_sat,EVENT-to-B_Sat,2,C

Sheet CT-to-HANI_Weekday
A1: Last Updated: | B1: 46181 | C1: Z1
A2: STATION | B2: COORDINATES | C2: 9901 | D2: 9903 | E2: 9905 | F2: 9907 | G2: 9909 | H2: 9911 | I2: 9913 | J2: 9915 | K2: 9917 | L2: 9919 | M2: 9921
A3: CAPE TOWN | B3: -33.92363127060243, 18.42718648501388 | C3: 0.2 | D3: 0.25347222 | E3: 0.30555556 | F3: 0.375 | G3: 0.43055556 | H3: 0.48611111 | I3: 0.55902778 | J3: 0.625 | K3: 0.67708333 | L3: 0.73263889 | M3: 0.80208333
A4: WOODSTOCK | B4: -33.925058308184404, 18.44613913370814
A5: SALT RIVER | B5: -33.92754558428959, 18.464689555116372
A6: KOEBERG RD | B6: -33.92570961024241, 18.47887742815667
A7: MAITLAND | B7: -33.92465193392986, 18.487001988940953
A8: NDABENI | B8: -33.928548273196824, 18.495159894144553
A9: PINELANDS | B9: -33.93964476336891, 18.490635019900687
A10: ESPLANADE | B10: -33.923640784366874, 18.446037955514498 | C10: 0.20694444 | D10: 0.26041667 | E10: 0.3125 | F10: 0.38194444 | G10: 0.4375 | H10: 0.49305556 | I10: 0.56597222 | J10: 0.63194444 | K10: 0.68402778 | L10: 0.73958333 | M10: 0.80902778
A11: YSTERPLAAT | B11: -33.9199022523178, 18.476775305514295 | C11: 0.21527778 | D11: 0.26875 | E11: 0.32083333 | F11: 0.39027778 | G11: 0.44583333 | H11: 0.50138889 | I11: 0.57430556 | J11: 0.64027778 | K11: 0.69236111 | L11: 0.74791667 | M11: 0.81736111
A12: MUTUAL | B12: -33.92209345116931, 18.511988082500565 | C12: 0.21875 | D12: 0.27222222 | E12: 0.32430556 | F12: 0.39375 | G12: 0.44930556 | H12: 0.50486111 | I12: 0.57777778 | J12: 0.64375 | K12: 0.69583333 | L12: 0.75138889 | M12: 0.82083333
A13: LANGA | B13: -33.938934072196076, 18.52974423065194 | C13: 0.22222222 | D13: 0.27569444 | E13: 0.32777778 | F13: 0.39722222 | G13: 0.45277778 | H13: 0.50833333 | I13: 0.58125 | J13: 0.64722222 | K13: 0.69930556 | L13: 0.75486111 | M13: 0.82430556
A14: BONTEHEUWEL | B14: -33.94185049480737, 18.549579817876847 | C14: 0.22361111 | D14: 0.27708333 | E14: 0.32916667 | F14: 0.39861111 | G14: 0.45416667 | H14: 0.50972222 | I14: 0.58263889 | J14: 0.64861111 | K14: 0.70069444 | L14: 0.75625 | M14: 0.82569444
A15: NETREG | B15: -33.952666168847884, 18.56356622880313 | C15: 0.225 | D15: 0.27847222 | E15: 0.33055556 | F15: 0.4 | G15: 0.45555556 | H15: 0.51111111 | I15: 0.58402778 | J15: 0.65 | K15: 0.70208333 | L15: 0.75763889 | M15: 0.82708333
A16: HEIDEVELD | B16: -33.969594701133275, 18.56187725551686 | C16: 0.22569444 | D16: 0.27916667 | E16: 0.33125 | F16: 0.40069444 | G16: 0.45625 | H16: 0.51180556 | I16: 0.58472222 | J16: 0.65069444 | K16: 0.70277778 | L16: 0.75833333 | M16: 0.82777778
A17: NYANGA | B17: -33.99271379632963, 18.559776951819032 | C17: 0.22847222 | D17: 0.28194444 | E17: 0.33402778 | F17: 0.40347222 | G17: 0.45902778 | H17: 0.51458333 | I17: 0.5875 | J17: 0.65347222 | K17: 0.70555556 | L17: 0.76111111 | M17: 0.83055556
A18: PHILIPPI | B18: -34.01328895709482, 18.584421561340882 | C18: 0.23263889 | D18: 0.28611111 | E18: 0.33819444 | F18: 0.40763889 | G18: 0.46319444 | H18: 0.51875 | I18: 0.59166667 | J18: 0.65763889 | K18: 0.70972222 | L18: 0.76527778 | M18: 0.83263889
A19: LENTEGEUR | B19: -34.03418971685345, 18.611322738328173
A20: MITCHELL'S PLAIN | B20: -34.0504610838304, 18.619222253671435
A21: KAPTEINSKLIP | B21: -34.06755873543257, 18.620534480658506
A22: STOCK ROAD | B22: -34.01412292128464, 18.606174209491407 | C22: 0.23541667 | D22: 0.28888889 | E22: 0.34097222 | F22: 0.41041667 | G22: 0.46597222 | H22: 0.52152778 | I22: 0.59444444 | J22: 0.66041667 | K22: 0.7125 | L22: 0.76805556 | M22: 0.83541667
A23: MANDALAY | B23: -34.019015667481014, 18.624391145998562 | C23: 0.23819444 | D23: 0.29166667 | E23: 0.34375 | F23: 0.41319444 | G23: 0.46875 | H23: 0.52430556 | I23: 0.59722222 | J23: 0.66319444 | K23: 0.71527778 | L23: 0.77083333 | M23: 0.83819444
A24: NOLUNGILE | B24: -34.016811809063164, 18.64902361716287 | C24: 0.24097222 | D24: 0.29444444 | E24: 0.34652778 | F24: 0.41597222 | G24: 0.47152778 | H24: 0.52708333 | I24: 0.6 | J24: 0.66597222 | K24: 0.71805556 | L24: 0.77361111 | M24: 0.84097222
A25: NONKQUBELA | B25: -34.02681746271161, 18.663190611341626 | C25: 0.24375 | D25: 0.29722222 | E25: 0.34930556 | F25: 0.41875 | G25: 0.47430556 | H25: 0.52986111 | I25: 0.60277778 | J25: 0.66875 | K25: 0.72083333 | L25: 0.77638889 | M25: 0.84375
A26: KHAYELITSHA | B26: -34.047943373751565, 18.67073769040669 | C26: 0.24652778 | D26: 0.3 | E26: 0.35208333 | F26: 0.42152778 | G26: 0.47708333 | H26: 0.53263889 | I26: 0.60555556 | J26: 0.67152778 | K26: 0.72361111 | L26: 0.77916667 | M26: 0.84652778
A27: KUYASA | B27: -34.05489939537871, 18.692323957717754 | C27: 0.24861111 | D27: 0.30208333 | E27: 0.35416667 | F27: 0.42361111 | G27: 0.47916667 | H27: 0.53472222 | I27: 0.60763889 | J27: 0.67361111 | K27: 0.72569444 | L27: 0.78125 | M27: 0.84861111
A28: CHRIS HANI | B28: -34.054706073305944, 18.710707924836054 | C28: 0.25138889 | D28: 0.30486111 | E28: 0.35486111 | F28: 0.42638889 | G28: 0.47986111 | H28: 0.5375 | I28: 0.61041667 | J28: 0.67430556 | K28: 0.72847222 | L28: 0.78402778 | M28: 0.85138889
A29: LAVISTOWN | B29: -33.943269567798055, 18.583722311337315
A30: BELHAR | B30: -33.93959717971092, 18.60894476900841
A31: UNIBELL | B31: -33.93686354314193, 18.628117540172582
A32: PENTECH | B32: -33.93468015167005, 18.646053668734744
A33: SAREPTA | B33: -33.92655594121331, 18.661143180651308
A34: BELLVILLE | B34: -33.906263459762684, 18.62662128465745

Sheet HANI-to-CT_Weekday
A1: Last Updated: | B1: 46181 | C1: Z1
A2: STATION | B2: COORDINATES | C2: 9900 | D2: 9902 | E2: 9904 | F2: 9906 | G2: 9908 | H2: 9910 | I2: 9912 | J2: 9914 | K2: 9916 | L2: 9918 | M2: 9920
A3: BELLVILLE | B3: -33.906263459762684, 18.62662128465745
A4: SAREPTA | B4: -33.92655594121331, 18.661143180651308
A5: PENTECH | B5: -33.93468015167005, 18.646053668734744
A6: UNIBELL | B6: -33.93686354314193, 18.628117540172582
A7: BELHAR | B7: -33.93959717971092, 18.60894476900841
A8: LAVISTOWN | B8: -33.943269567798055, 18.583722311337315
A9: CHRIS HANI | B9: -34.054706073305944, 18.710707924836054 | C9: 0.20486111 | D9: 0.25833333 | E9: 0.3125 | F9: 0.3625 | G9: 0.43194444 | H9: 0.48958333 | I9: 0.54861111 | J9: 0.62638889 | K9: 0.68402778 | L9: 0.73611111 | M9: 0.79861111
A10: KUYASA | B10: -34.05489939537871, 18.692323957717754 | C10: 0.20763889 | D10: 0.26111111 | E10: 0.31527778 | F10: 0.36527778 | G10: 0.43472222 | H10: 0.49236111 | I10: 0.55138889 | J10: 0.62916667 | K10: 0.68680556 | L10: 0.73888889 | M10: 0.80138889
A11: KHAYELITSHA | B11: -34.047943373751565, 18.67073769040669 | C11: 0.20972222 | D11: 0.26319444 | E11: 0.31736111 | F11: 0.36736111 | G11: 0.43680556 | H11: 0.49444444 | I11: 0.55347222 | J11: 0.63125 | K11: 0.68888889 | L11: 0.74097222 | M11: 0.80347222
A12: NONKQUBELA | B12: -34.02681746271161, 18.663190611341626 | C12: 0.2125 | D12: 0.26597222 | E12: 0.32013889 | F12: 0.37013889 | G12: 0.43958333 | H12: 0.49722222 | I12: 0.55625 | J12: 0.63402778 | K12: 0.69166667 | L12: 0.74375 | M12: 0.80625
A13: NOLUNGILE | B13: -34.016811809063164, 18.64902361716287 | C13: 0.21527778 | D13: 0.26875 | E13: 0.32291667 | F13: 0.37291667 | G13: 0.44236111 | H13: 0.5 | I13: 0.55902778 | J13: 0.63680556 | K13: 0.69444444 | L13: 0.74652778 | M13: 0.80902778
A14: MANDALAY | B14: -34.019015667481014, 18.624391145998562 | C14: 0.21805556 | D14: 0.27152778 | E14: 0.32569444 | F14: 0.37569444 | G14: 0.44513889 | H14: 0.50277778 | I14: 0.56180556 | J14: 0.63958333 | K14: 0.69722222 | L14: 0.74930556 | M14: 0.81180556
A15: STOCK ROAD | B15: -34.01412292128464, 18.606174209491407 | C15: 0.22013889 | D15: 0.27361111 | E15: 0.32777778 | F15: 0.37777778 | G15: 0.44722222 | H15: 0.50486111 | I15: 0.56388889 | J15: 0.64166667 | K15: 0.69930556 | L15: 0.75138889 | M15: 0.81388889
A16: KAPTEINSKLIP | B16: -34.06755873543257, 18.620534480658506
A17: MITCHELL'S PLAIN | B17: -34.0504610838304, 18.619222253671435
A18: LENTEGEUR | B18: -34.03418971685345, 18.611322738328173
A19: PHILIPPI | B19: -34.01328895709482, 18.584421561340882 | C19: 0.22361111 | D19: 0.27708333 | E19: 0.33125 | F19: 0.38125 | G19: 0.45069444 | H19: 0.50833333 | I19: 0.56736111 | J19: 0.64513889 | K19: 0.70277778 | L19: 0.75486111 | M19: 0.81736111
A20: NYANGA | B20: -33.99271379632963, 18.559776951819032 | C20: 0.22638889 | D20: 0.27986111 | E20: 0.33402778 | F20: 0.38402778 | G20: 0.45347222 | H20: 0.51111111 | I20: 0.57013889 | J20: 0.64791667 | K20: 0.70555556 | L20: 0.75763889 | M20: 0.82013889
A21: HEIDEVELD | B21: -33.96955914627068, 18.561952615501543 | C21: 0.22777778 | D21: 0.28125 | E21: 0.33541667 | F21: 0.38541667 | G21: 0.45486111 | H21: 0.5125 | I21: 0.57152778 | J21: 0.64930556 | K21: 0.70694444 | L21: 0.75902778 | M21: 0.82152778
A22: NETREG | B22: -33.952620288476226, 18.563580552945645 | C22: 0.22916667 | D22: 0.28263889 | E22: 0.33680556 | F22: 0.38680556 | G22: 0.45625 | H22: 0.51388889 | I22: 0.57291667 | J22: 0.65069444 | K22: 0.70833333 | L22: 0.76041667 | M22: 0.82291667
A23: BONTEHEUWEL | B23: -33.94185049480737, 18.549579817876847 | C23: 0.23055556 | D23: 0.28402778 | E23: 0.33819444 | F23: 0.38819444 | G23: 0.45763889 | H23: 0.51527778 | I23: 0.57430556 | J23: 0.65208333 | K23: 0.70972222 | L23: 0.76180556 | M23: 0.82430556
A24: LANGA | B24: -33.938934072196076, 18.52974423065194 | C24: 0.23263889 | D24: 0.28611111 | E24: 0.34027778 | F24: 0.39027778 | G24: 0.45972222 | H24: 0.51736111 | I24: 0.57638889 | J24: 0.65416667 | K24: 0.71180556 | L24: 0.76388889 | M24: 0.82638889
A25: MUTUAL | B25: -33.92209345116931, 18.511988082500565 | C25: 0.23611111 | D25: 0.28958333 | E25: 0.34375 | F25: 0.39375 | G25: 0.46319444 | H25: 0.52083333 | I25: 0.57986111 | J25: 0.65763889 | K25: 0.71527778 | L25: 0.76736111 | M25: 0.82986111
A26: YSTERPLAAT | B26: -33.9199022523178, 18.476775305514295 | C26: 0.24236111 | D26: 0.29583333 | E26: 0.35 | F26: 0.4 | G26: 0.46944444 | H26: 0.52708333 | I26: 0.58611111 | J26: 0.66388889 | K26: 0.72152778 | L26: 0.77361111 | M26: 0.83611111
